Workbook

Sheet Enero
C2: #VALUE! | AB2: Código: IERLJ_AE_06
AB4: Página: 1 de 1
AB6: Versión: 1.0
C7: SEGUIMIENTO A LA ASISTENCIA
A9: Docente: | C9: Andres Paz | H9: Sede | U9: Área/Asignaura
A10: Sede | K10: Mes | AB10: Año
A11: N° | B11: GRADO | C11: NOMBRES Y APELLIDOS | D11: 19 | E11: 20 | F11: 21 | G11: 22 | H11: 23 | J11: 26 | K11: 27 | L11: 28 | M11: 29 | N11: 30 | P11: ASISTENCIA | Q11: FALTAS | R11: TARDE | S11: UNIFORME | T11: JUSTIFICACIÓN | U11: % ASISTENCIA | X11: VALORES PARA LLENAR LA ASISTENCIA
A12: 1 | B12: 6 | C12: Barrientos Gallo Juan Sebastian | D12: J | E12: J | F12: J | G12: J | H12: J | J12: J | K12: J | L12: J | M12: J | N12: J | P12: =COUNTIF(D12:N12, 1) + COUNTIF(D12:N12, "U")+ COUNTIF(D12:N12, "T") + COUNTIF(D12:N12, "J") -> 10 | Q12: =COUNTIF(D12:N12,0) -> 0 | R12: =COUNTIF(D12:N12,"T") -> 0 | S12: =COUNTIF(D12:N12,"U") -> 0 | T12: =COUNTIF(D12:N12,"J") -> 10 | U12: =SUM(P12)/COUNTA($D$11:$N$11) -> 1
A13: 2 | B13: 6 | C13: Dávila Bedoya Kevin Alejandro | D13: 1 | E13: 1 | F13: 1 | G13: 1 | H13: 1 | J13: 1 | K13: 1 | L13: 1 | M13: 1 | N13: 1 | P13: =COUNTIF(D13:N13, 1) + COUNTIF(D13:N13, "U")+ COUNTIF(D13:N13, "T") + COUNTIF(D13:N13, "J") -> 10 | Q13: =COUNTIF(D13:N13,0) -> 0 | R13: =COUNTIF(D13:N13,"T") -> 0 | S13: =COUNTIF(D13:N13,"U") -> 0 | T13: =COUNTIF(D13:N13,"J") -> 0 | U13: =SUM(P13)/COUNTA($D$11:$N$11) -> 1 | Y13: 1 | Z13: Asistio
A14: 3 | B14: 6 | C14: Franco Barraza Maria Jose | D14: 1 | E14: 1 | F14: 1 | G14: 1 | H14: 1 | J14: 1 | K14: 1 | L14: 1 | M14: 1 | N14: 1 | P14: =COUNTIF(D14:N14, 1) + COUNTIF(D14:N14, "U")+ COUNTIF(D14:N14, "T") + COUNTIF(D14:N14, "J") -> 10 | Q14: =COUNTIF(D14:N14,0) -> 0 | R14: =COUNTIF(D14:N14,"T") -> 0 | S14: =COUNTIF(D14:N14,"U") -> 0 | T14: =COUNTIF(D14:N14,"J") -> 0 | U14: =SUM(P14)/COUNTA($D$11:$N$11) -> 1 | Y14: 0 | Z14: No asistio (faltas)
A15: 4 | B15: 6 | C15: Vera Figuera Branyelis Del Carmen | D15: 1 | E15: 0 | F15: 1 | G15: 1 | H15: 1 | J15: U | K15: 1 | L15: 1 | M15: 1 | N15: 1 | P15: =COUNTIF(D15:N15, 1) + COUNTIF(D15:N15, "U")+ COUNTIF(D15:N15, "T") + COUNTIF(D15:N15, "J") -> 9 | Q15: =COUNTIF(D15:N15,0) -> 1 | R15: =COUNTIF(D15:N15,"T") -> 0 | S15: =COUNTIF(D15:N15,"U") -> 1 | T15: =COUNTIF(D15:N15,"J") -> 0 | U15: =SUM(P15)/COUNTA($D$11:$N$11) -> 0.9 | Y15: T | Z15: Llegada tarde
A16: 5 | B16: 7 | C16: Adrianza Figuera Brainer Josué | D16: 1 | E16: 1 | F16: 1 | G16: 1 | H16: 1 | J16: 1 | K16: 1 | L16: 1 | M16: 1 | N16: 1 | P16: =COUNTIF(D16:N16, 1) + COUNTIF(D16:N16, "U")+ COUNTIF(D16:N16, "T") + COUNTIF(D16:N16, "J") -> 10 | Q16: =COUNTIF(D16:N16,0) -> 0 | R16: =COUNTIF(D16:N16,"T") -> 0 | S16: =COUNTIF(D16:N16,"U") -> 0 | T16: =COUNTIF(D16:N16,"J") -> 0 | U16: =SUM(P16)/COUNTA($D$11:$N$11) -> 1 | Y16: J | Z16: Justificación
A17: 6 | B17: 7 | C17: Chavarría Valencia Dylan Alexis | D17: 1 | E17: 1 | F17: 1 | G17: 1 | H17: 1 | J17: 1 | K17: 1 | L17: 1 | M17: 1 | N17: 1 | P17: =COUNTIF(D17:N17, 1) + COUNTIF(D17:N17, "U")+ COUNTIF(D17:N17, "T") + COUNTIF(D17:N17, "J") -> 10 | Q17: =COUNTIF(D17:N17,0) -> 0 | R17: =COUNTIF(D17:N17,"T") -> 0 | S17: =COUNTIF(D17:N17,"U") -> 0 | T17: =COUNTIF(D17:N17,"J") -> 0 | U17: =SUM(P17)/COUNTA($D$11:$N$11) -> 1 | Y17: U | Z17: Uniforme
A18: 7 | B18: 7 | C18: Giraldo Ceballos Miguel Angel | D18: 1 | E18: 1 | F18: J | G18: 1 | H18: 1 | J18: 1 | K18: 1 | L18: 1 | M18: 1 | N18: 1 | P18: =COUNTIF(D18:N18, 1) + COUNTIF(D18:N18, "U")+ COUNTIF(D18:N18, "T") + COUNTIF(D18:N18, "J") -> 10 | Q18: =COUNTIF(D18:N18,0) -> 0 | R18: =COUNTIF(D18:N18,"T") -> 0 | S18: =COUNTIF(D18:N18,"U") -> 0 | T18: =COUNTIF(D18:N18,"J") -> 1 | U18: =SUM(P18)/COUNTA($D$11:$N$11) -> 1
A19: 8 | B19: 7 | C19: Hincapié Muñoz Juan Pablo | D19: J | E19: J | F19: J | G19: 1 | H19: 1 | J19: 1 | K19: 1 | L19: 1 | M19: 1 | N19: 1 | P19: =COUNTIF(D19:N19, 1) + COUNTIF(D19:N19, "U")+ COUNTIF(D19:N19, "T") + COUNTIF(D19:N19, "J") -> 10 | Q19: =COUNTIF(D19:N19,0) -> 0 | R19: =COUNTIF(D19:N19,"T") -> 0 | S19: =COUNTIF(D19:N19,"U") -> 0 | T19: =COUNTIF(D19:N19,"J") -> 3 | U19: =SUM(P19)/COUNTA($D$11:$N$11) -> 1
A20: 9 | B20: 7 | C20: Jiménez Muñoz Alejandro | D20: 0 | E20: 0 | F20: 1 | G20: 1 | H20: 1 | J20: 1 | K20: 1 | L20: U | M20: 1 | N20: 1 | P20: =COUNTIF(D20:N20, 1) + COUNTIF(D20:N20, "U")+ COUNTIF(D20:N20, "T") + COUNTIF(D20:N20, "J") -> 8 | Q20: =COUNTIF(D20:N20,0) -> 2 | R20: =COUNTIF(D20:N20,"T") -> 0 | S20: =COUNTIF(D20:N20,"U") -> 1 | T20: =COUNTIF(D20:N20,"J") -> 0 | U20: =SUM(P20)/COUNTA($D$11:$N$11) -> 0.8
A21: 10 | B21: 7 | C21: Rodríguez Correa Dubian Esteban | D21: 1 | E21: 1 | F21: 1 | G21: 1 | H21: 1 | J21: 1 | K21: 1 | L21: 1 | M21: 1 | N21: 1 | P21: =COUNTIF(D21:N21, 1) + COUNTIF(D21:N21, "U")+ COUNTIF(D21:N21, "T") + COUNTIF(D21:N21, "J") -> 10 | Q21: =COUNTIF(D21:N21,0) -> 0 | R21: =COUNTIF(D21:N21,"T") -> 0 | S21: =COUNTIF(D21:N21,"U") -> 0 | T21: =COUNTIF(D21:N21,"J") -> 0 | U21: =SUM(P21)/COUNTA($D$11:$N$11) -> 1
A22: 11 | B22: 7 | C22: Valencia Virgen Alexandra | D22: 1 | E22: 1 | F22: 1 | G22: 1 | H22: 1 | J22: U | K22: 1 | L22: 1 | M22: 1 | N22: 1 | P22: =COUNTIF(D22:N22, 1) + COUNTIF(D22:N22, "U")+ COUNTIF(D22:N22, "T") + COUNTIF(D22:N22, "J") -> 10 | Q22: =COUNTIF(D22:N22,0) -> 0 | R22: =COUNTIF(D22:N22,"T") -> 0 | S22: =COUNTIF(D22:N22,"U") -> 1 | T22: =COUNTIF(D22:N22,"J") -> 0 | U22: =SUM(P22)/COUNTA($D$11:$N$11) -> 1
A23: 12 | B23: 8 | C23: Caviedes Hernández Juan Manuel | D23: J | E23: J | F23: J | G23: 1 | H23: 1 | J23: U | K23: 1 | L23: 1 | M23: 1 | N23: 1 | P23: =COUNTIF(D23:N23, 1) + COUNTIF(D23:N23, "U")+ COUNTIF(D23:N23, "T") + COUNTIF(D23:N23, "J") -> 10 | Q23: =COUNTIF(D23:N23,0) -> 0 | R23: =COUNTIF(D23:N23,"T") -> 0 | S23: =COUNTIF(D23:N23,"U") -> 1 | T23: =COUNTIF(D23:N23,"J") -> 3 | U23: =SUM(P23)/COUNTA($D$11:$N$11) -> 1
A24: 13 | B24: 8 | C24: Orozco Chavarría Cristóbal | D24: 1 | E24: 1 | F24: 1 | G24: 1 | H24: 1 | J24: 1 | K24: 1 | L24: U | M24: 1 | N24: U | P24: =COUNTIF(D24:N24, 1) + COUNTIF(D24:N24, "U")+ COUNTIF(D24:N24, "T") + COUNTIF(D24:N24, "J") -> 10 | Q24: =COUNTIF(D24:N24,0) -> 0 | R24: =COUNTIF(D24:N24,"T") -> 0 | S24: =COUNTIF(D24:N24,"U") -> 2 | T24: =COUNTIF(D24:N24,"J") -> 0 | U24: =SUM(P24)/COUNTA($D$11:$N$11) -> 1
A25: 14 | B25: 8 | C25: Velásquez Muñoz Anyely Tatiana | D25: 1 | E25: 1 | F25: 1 | G25: 1 | H25: 1 | J25: U | K25: U | L25: 1 | M25: 1 | N25: 1 | P25: =COUNTIF(D25:N25, 1) + COUNTIF(D25:N25, "U")+ COUNTIF(D25:N25, "T") + COUNTIF(D25:N25, "J") -> 10 | Q25: =COUNTIF(D25:N25,0) -> 0 | R25: =COUNTIF(D25:N25,"T") -> 0 | S25: =COUNTIF(D25:N25,"U") -> 2 | T25: =COUNTIF(D25:N25,"J") -> 0 | U25: =SUM(P25)/COUNTA($D$11:$N$11) -> 1
A26: 15 | B26: 9 | C26: Dávila Bedoya Evelin Sofía | D26: 1 | E26: 1 | F26: 1 | G26: 1 | H26: 1 | J26: 1 | K26: 1 | L26: 1 | M26: 1 | N26: 1 | P26: =COUNTIF(D26:N26, 1) + COUNTIF(D26:N26, "U")+ COUNTIF(D26:N26, "T") + COUNTIF(D26:N26, "J") -> 10 | Q26: =COUNTIF(D26:N26,0) -> 0 | R26: =COUNTIF(D26:N26,"T") -> 0 | S26: =COUNTIF(D26:N26,"U") -> 0 | T26: =COUNTIF(D26:N26,"J") -> 0 | U26: =SUM(P26)/COUNTA($D$11:$N$11) -> 1
A27: 16 | B27: 9 | C27: Duque Aristizabal Ángel Gabriel | D27: 1 | E27: 1 | F27: 1 | G27: 1 | H27: U | J27: 1 | K27: 1 | L27: 1 | M27: 1 | N27: 1 | P27: =COUNTIF(D27:N27, 1) + COUNTIF(D27:N27, "U")+ COUNTIF(D27:N27, "T") + COUNTIF(D27:N27, "J") -> 10 | Q27: =COUNTIF(D27:N27,0) -> 0 | R27: =COUNTIF(D27:N27,"T") -> 0 | S27: =COUNTIF(D27:N27,"U") -> 1 | T27: =COUNTIF(D27:N27,"J") -> 0 | U27: =SUM(P27)/COUNTA($D$11:$N$11) -> 1
A28: 17 | B28: 9 | C28: Eusse Castañeda María Fernanda | D28: 1 | E28: 1 | F28: 1 | G28: 1 | H28: 1 | J28: 1 | K28: 1 | L28: 1 | M28: 1 | N28: 1 | P28: =COUNTIF(D28:N28, 1) + COUNTIF(D28:N28, "U")+ COUNTIF(D28:N28, "T") + COUNTIF(D28:N28, "J") -> 10 | Q28: =COUNTIF(D28:N28,0) -> 0 | R28: =COUNTIF(D28:N28,"T") -> 0 | S28: =COUNTIF(D28:N28,"U") -> 0 | T28: =COUNTIF(D28:N28,"J") -> 0 | U28: =SUM(P28)/COUNTA($D$11:$N$11) -> 1
A29: 18 | B29: 9 | C29: Franco Barraza Gyshet Johanna | D29: 1 | E29: 1 | F29: 1 | G29: 1 | H29: 1 | J29: 1 | K29: 1 | L29: 1 | M29: 1 | N29: 1 | P29: =COUNTIF(D29:N29, 1) + COUNTIF(D29:N29, "U")+ COUNTIF(D29:N29, "T") + COUNTIF(D29:N29, "J") -> 10 | Q29: =COUNTIF(D29:N29,0) -> 0 | R29: =COUNTIF(D29:N29,"T") -> 0 | S29: =COUNTIF(D29:N29,"U") -> 0 | T29: =COUNTIF(D29:N29,"J") -> 0 | U29: =SUM(P29)/COUNTA($D$11:$N$11) -> 1
A30: 19 | B30: 9 | C30: Giraldo Giraldo Juan Camilo | D30: 1 | E30: 1 | F30: 1 | G30: 1 | H30: 1 | J30: 1 | K30: 1 | L30: 1 | M30: 1 | N30: 1 | P30: =COUNTIF(D30:N30, 1) + COUNTIF(D30:N30, "U")+ COUNTIF(D30:N30, "T") + COUNTIF(D30:N30, "J") -> 10 | Q30: =COUNTIF(D30:N30,0) -> 0 | R30: =COUNTIF(D30:N30,"T") -> 0 | S30: =COUNTIF(D30:N30,"U") -> 0 | T30: =COUNTIF(D30:N30,"J") -> 0 | U30: =SUM(P30)/COUNTA($D$11:$N$11) -> 1
A31: 20 | B31: 9 | C31: Gómez Vergara Michael Estiven | D31: 1 | E31: 1 | F31: 1 | G31: 1 | H31: 1 | J31: 1 | K31: 1 | L31: 1 | M31: 1 | N31: 1 | P31: =COUNTIF(D31:N31, 1) + COUNTIF(D31:N31, "U")+ COUNTIF(D31:N31, "T") + COUNTIF(D31:N31, "J") -> 10 | Q31: =COUNTIF(D31:N31,0) -> 0 | R31: =COUNTIF(D31:N31,"T") -> 0 | S31: =COUNTIF(D31:N31,"U") -> 0 | T31: =COUNTIF(D31:N31,"J") -> 0 | U31: =SUM(P31)/COUNTA($D$11:$N$11) -> 1
A32: 21 | B32: 9 | C32: López Aguirre Alexis | D32: 1 | E32: 1 | F32: 1 | G32: 1 | H32: 1 | J32: 1 | K32: 1 | L32: 1 | M32: 1 | N32: 1 | P32: =COUNTIF(D32:N32, 1) + COUNTIF(D32:N32, "U")+ COUNTIF(D32:N32, "T") + COUNTIF(D32:N32, "J") -> 10 | Q32: =COUNTIF(D32:N32,0) -> 0 | R32: =COUNTIF(D32:N32,"T") -> 0 | S32: =COUNTIF(D32:N32,"U") -> 0 | T32: =COUNTIF(D32:N32,"J") -> 0 | U32: =SUM(P32)/COUNTA($D$11:$N$11) -> 1
A33: 22 | B33: 10 | C33: Duque Aristizabal Yennifer | D33: 1 | E33: 1 | F33: 1 | G33: 1 | H33: 1 | J33: 1 | K33: 1 | L33: 1 | M33: 1 | N33: 1 | P33: =COUNTIF(D33:N33, 1) + COUNTIF(D33:N33, "U")+ COUNTIF(D33:N33, "T") + COUNTIF(D33:N33, "J") -> 10 | Q33: =COUNTIF(D33:N33,0) -> 0 | R33: =COUNTIF(D33:N33,"T") -> 0 | S33: =COUNTIF(D33:N33,"U") -> 0 | T33: =COUNTIF(D33:N33,"J") -> 0 | U33: =SUM(P33)/COUNTA($D$11:$N$11) -> 1
A34: 23 | B34: 10 | C34: García Navarro Sebastian Camilo | D34: 1 | E34: 1 | F34: 1 | G34: 1 | H34: 1 | J34: 1 | K34: 1 | L34: 1 | M34: 1 | N34: 1 | P34: =COUNTIF(D34:N34, 1) + COUNTIF(D34:N34, "U")+ COUNTIF(D34:N34, "T") + COUNTIF(D34:N34, "J") -> 10 | Q34: =COUNTIF(D34:N34,0) -> 0 | R34: =COUNTIF(D34:N34,"T") -> 0 | S34: =COUNTIF(D34:N34,"U") -> 0 | T34: =COUNTIF(D34:N34,"J") -> 0 | U34: =SUM(P34)/COUNTA($D$11:$N$11) -> 1
A35: 24 | B35: 10 | C35: Gallego Giraldo Marlon | D35: 1 | E35: 1 | F35: 1 | G35: 1 | H35: 1 | J35: 1 | K35: 1 | L35: 1 | M35: 1 | N35: U | P35: =COUNTIF(D35:N35, 1) + COUNTIF(D35:N35, "U")+ COUNTIF(D35:N35, "T") + COUNTIF(D35:N35, "J") -> 10 | Q35: =COUNTIF(D35:N35,0) -> 0 | R35: =COUNTIF(D35:N35,"T") -> 0 | S35: =COUNTIF(D35:N35,"U") -> 1 | T35: =COUNTIF(D35:N35,"J") -> 0 | U35: =SUM(P35)/COUNTA($D$11:$N$11) -> 1
A36: 25 | B36: 10 | C36: Gómez Pamplona Julieta | D36: 1 | E36: 1 | F36: 1 | G36: 1 | H36: 1 | J36: 1 | K36: 1 | L36: 1 | M36: 1 | N36: 1 | P36: =COUNTIF(D36:N36, 1) + COUNTIF(D36:N36, "U")+ COUNTIF(D36:N36, "T") + COUNTIF(D36:N36, "J") -> 10 | Q36: =COUNTIF(D36:N36,0) -> 0 | R36: =COUNTIF(D36:N36,"T") -> 0 | S36: =COUNTIF(D36:N36,"U") -> 0 | T36: =COUNTIF(D36:N36,"J") -> 0 | U36: =SUM(P36)/COUNTA($D$11:$N$11) -> 1
A37: 26 | B37: 10 | C37: González Martínez Salomé | D37: 0 | E37: 0 | F37: 1 | G37: 1 | H37: U | J37: T | K37: 1 | L37: U | M37: 1 | N37: 1 | P37: =COUNTIF(D37:N37, 1) + COUNTIF(D37:N37, "U")+ COUNTIF(D37:N37, "T") + COUNTIF(D37:N37, "J") -> 7 | Q37: =COUNTIF(D37:N37,0) -> 2 | R37: =COUNTIF(D37:N37,"T") -> 0 | S37: =COUNTIF(D37:N37,"U") -> 2 | T37: =COUNTIF(D37:N37,"J") -> 0 | U37: =SUM(P37)/COUNTA($D$11:$N$11) -> 0.7
A38: 27 | B38: 10 | C38: Lezcano Morillo Edwin Alexander | D38: J | E38: J | F38: J | G38: J | H38: J | J38: J | K38: J | L38: J | M38: J | N38: J | P38: =COUNTIF(D38:N38, 1) + COUNTIF(D38:N38, "U")+ COUNTIF(D38:N38, "T") + COUNTIF(D38:N38, "J") -> 10 | Q38: =COUNTIF(D38:N38,0) -> 0 | R38: =COUNTIF(D38:N38,"T") -> 0 | S38: =COUNTIF(D38:N38,"U") -> 0 | T38: =COUNTIF(D38:N38,"J") -> 10 | U38: =SUM(P38)/COUNTA($D$11:$N$11) -> 1
A39: 28 | B39: 10 | C39: Valencia Vásquez Anderson | D39: 1 | E39: 1 | F39: 1 | G39: U | H39: U | J39: 1 | K39: U | L39: 1 | M39: 1 | N39: U | P39: =COUNTIF(D39:N39, 1) + COUNTIF(D39:N39, "U")+ COUNTIF(D39:N39, "T") -> 10 | Q39: =COUNTIF(D39:N39,0) -> 0 | R39: =COUNTIF(D39:N39,"T") -> 0 | S39: =COUNTIF(D39:N39,"U") -> 4 | T39: =COUNTIF(D39:N39,"J") -> 0 | U39: =SUM(P39)/COUNTA(D37:N37) -> 1
A40: 29 | B40: 11 | C40: Caviedes Hernández Cristina | D40: J | E40: J | F40: J | G40: J | H40: J | J40: 1 | K40: 1 | L40: U | M40: 1 | N40: U | P40: =COUNTIF(D40:N40, 1) + COUNTIF(D40:N40, "U")+ COUNTIF(D40:N40, "T") -> 5 | Q40: =COUNTIF(D40:N40,0) -> 0 | R40: =COUNTIF(D40:N40,"T") -> 0 | S40: =COUNTIF(D40:N40,"U") -> 2 | T40: =COUNTIF(D40:N40,"J") -> 5 | U40: =SUM(P40)/COUNTA(D39:N39) -> 0.5

Sheet Febrero
C2: #VALUE! | AA2: Código: IERLJ_AE_06
AA4: Página: 1 de 1
AA6: Versión: 1.0
C7: SEGUIMIENTO A LA ASISTENCIA
A9: Docente: | H9: Sede | T9: Área/Asignaura
A10: Sede | K10: Mes | AA10: Año
A11: N° | B11: GRADO | C11: NOMBRES Y APELLIDOS | D11: 2 | E11: 3 | F11: 4 | G11: 5 | H11: 6 | J11: 9 | K11: 10 | L11: 11 | M11: 12 | N11: 13 | P11: 16 | Q11: 17 | R11: 18 | S11: 19 | T11: 20 | V11: 23 | W11: 24 | X11: 25 | Y11: 26 | Z11: 27 | AB11: ASISTENCIA | AC11: FALTAS | AD11: TARDE | AE11: UNIFORME | AF11: JUSTIFICACIÓN | AG11: % ASISTENCIA | AJ11: VALORES PARA LLENAR LA ASISTENCIA
A12: 1 | B12: 6 | C12: Barrientos Gallo Juan Sebastian | D12: 1 | E12: 1 | F12: 1 | G12: 1 | H12: 1 | J12: 1 | K12: 1 | L12: 1 | M12: 1 | N12: 1 | P12: 1 | Q12: 1 | R12: 1 | S12: 1 | T12: 1 | AB12: {=COUNTIF(D12:Z12,1)+COUNTIF(D12:Z12,U)+COUNTIF(D12:Z12,_xleta.T)+COUNTIF(D12:Z12,J)} -> 15 | AC12: =COUNTIF(D12:Z12,0) -> 0 | AD12: =COUNTIF(D12:Z12,"T") -> 0 | AE12: =COUNTIF(D12:Z12,"U") -> 0 | AF12: =COUNTIF(D12:Z12,"J") -> 0 | AG12: =SUM(AB12)/20 -> 0.75
A13: 2 | B13: =Enero!B13 -> 6 | C13: =Enero!C13 -> Dávila Bedoya Kevin Alejandro | D13: 1 | E13: 1 | F13: 1 | G13: 1 | H13: 1 | J13: 1 | K13: 1 | L13: 1 | M13: 1 | N13: 1 | P13: 1 | Q13: 1 | R13: 1 | S13: 1 | T13: 1 | AB13: {=COUNTIF(D13:Z13,1)+COUNTIF(D13:Z13,U)+COUNTIF(D13:Z13,_xleta.T)+COUNTIF(D13:Z13,J)} -> 15 | AC13: =COUNTIF(D13:Z13,0) -> 0 | AD13: =COUNTIF(D13:Z13,"T") -> 0 | AE13: =COUNTIF(D13:Z13,"U") -> 0 | AF13: =COUNTIF(D13:Z13,"J") -> 0 | AG13: =SUM(AB13)/20 -> 0.75 | AK13: 1 | AL13: Asistio
A14: 3 | B14: =Enero!B14 -> 6 | C14: =Enero!C14 -> Franco Barraza Maria Jose | D14: 1 | E14: 1 | F14: 1 | G14: 1 | H14: 1 | J14: 1 | K14: U | L14: 1 | M14: 1 | N14: 1 | P14: 1 | Q14: 1 | R14: U | S14: 1 | T14: 1 | AB14: {=COUNTIF(D14:Z14,1)+COUNTIF(D14:Z14,U)+COUNTIF(D14:Z14,_xleta.T)+COUNTIF(D14:Z14,J)} -> 13 | AC14: =COUNTIF(D14:Z14,0) -> 0 | AD14: =COUNTIF(D14:Z14,"T") -> 0 | AE14: =COUNTIF(D14:Z14,"U") -> 2 | AF14: =COUNTIF(D14:Z14,"J") -> 0 | AG14: =SUM(AB14)/20 -> 0.65 | AK14: 0 | AL14: No asistio (faltas)
A15: 4 | B15: =Enero!B15 -> 6 | C15: =Enero!C15 -> Vera Figuera Branyelis Del Carmen | D15: 1 | E15: 1 | F15: 1 | G15: 1 | H15: 1 | J15: 1 | K15: 1 | L15: 1 | M15: 1 | N15: 1 | P15: 1 | Q15: 1 | R15: 1 | S15: 1 | T15: 1 | AB15: {=COUNTIF(D15:Z15,1)+COUNTIF(D15:Z15,U)+COUNTIF(D15:Z15,_xleta.T)+COUNTIF(D15:Z15,J)} -> 15 | AC15: =COUNTIF(D15:Z15,0) -> 0 | AD15: =COUNTIF(D15:Z15,"T") -> 0 | AE15: =COUNTIF(D15:Z15,"U") -> 0 | AF15: =COUNTIF(D15:Z15,"J") -> 0 | AG15: =SUM(AB15)/20 -> 0.75 | AK15: T | AL15: Llegada tarde
A16: 5 | B16: =Enero!B16 -> 7 | C16: =Enero!C16 -> Adrianza Figuera Brainer Josué | D16: 1 | E16: 1 | F16: U | G16: 1 | H16: 1 | J16: 1 | K16: 1 | L16: 1 | M16: 1 | N16: 1 | P16: 1 | Q16: 1 | R16: 1 | S16: 1 | T16: 1 | AB16: {=COUNTIF(D16:Z16,1)+COUNTIF(D16:Z16,U)+COUNTIF(D16:Z16,_xleta.T)+COUNTIF(D16:Z16,J)} -> 14 | AC16: =COUNTIF(D16:Z16,0) -> 0 | AD16: =COUNTIF(D16:Z16,"T") -> 0 | AE16: =COUNTIF(D16:Z16,"U") -> 1 | AF16: =COUNTIF(D16:Z16,"J") -> 0 | AG16: =SUM(AB16)/20 -> 0.7 | AK16: J | AL16: Justificación
A17: 6 | B17: =Enero!B17 -> 7 | C17: =Enero!C17 -> Chavarría Valencia Dylan Alexis | D17: 1 | E17: 1 | F17: 1 | G17: 1 | H17: 1 | J17: 1 | K17: 1 | L17: 1 | M17: 1 | N17: 1 | P17: 1 | Q17: 1 | R17: 1 | S17: 1 | T17: 1 | AB17: {=COUNTIF(D17:Z17,1)+COUNTIF(D17:Z17,U)+COUNTIF(D17:Z17,_xleta.T)+COUNTIF(D17:Z17,J)} -> 15 | AC17: =COUNTIF(D17:Z17,0) -> 0 | AD17: =COUNTIF(D17:Z17,"T") -> 0 | AE17: =COUNTIF(D17:Z17,"U") -> 0 | AF17: =COUNTIF(D17:Z17,"J") -> 0 | AG17: =SUM(AB17)/20 -> 0.75 | AK17: U | AL17: Uniforme
A18: 7 | B18: =Enero!B18 -> 7 | C18: =Enero!C18 -> Giraldo Ceballos Miguel Angel | D18: 1 | E18: 1 | F18: 1 | G18: 1 | H18: 1 | J18: 1 | K18: 1 | L18: 1 | M18: 1 | N18: 1 | P18: 1 | Q18: 1 | R18: 1 | S18: 1 | T18: 1 | AB18: {=COUNTIF(D18:Z18,1)+COUNTIF(D18:Z18,U)+COUNTIF(D18:Z18,_xleta.T)+COUNTIF(D18:Z18,J)} -> 15 | AC18: =COUNTIF(D18:Z18,0) -> 0 | AD18: =COUNTIF(D18:Z18,"T") -> 0 | AE18: =COUNTIF(D18:Z18,"U") -> 0 | AF18: =COUNTIF(D18:Z18,"J") -> 0 | AG18: =SUM(AB18)/20 -> 0.75
A19: 8 | B19: =Enero!B19 -> 7 | C19: =Enero!C19 -> Hincapié Muñoz Juan Pablo | D19: J | E19: 1 | F19: 1 | G19: 1 | H19: 1 | J19: 1 | K19: 1 | L19: 1 | M19: 1 | N19: 1 | P19: 1 | Q19: 1 | R19: 1 | S19: 1 | T19: 1 | AB19: {=COUNTIF(D19:Z19,1)+COUNTIF(D19:Z19,U)+COUNTIF(D19:Z19,_xleta.T)+COUNTIF(D19:Z19,J)} -> 14 | AC19: =COUNTIF(D19:Z19,0) -> 0 | AD19: =COUNTIF(D19:Z19,"T") -> 0 | AE19: =COUNTIF(D19:Z19,"U") -> 0 | AF19: =COUNTIF(D19:Z19,"J") -> 1 | AG19: =SUM(AB19)/20 -> 0.7
A20: 9 | B20: =Enero!B20 -> 7 | C20: =Enero!C20 -> Jiménez Muñoz Alejandro | D20: 1 | E20: 1 | F20: U | G20: 1 | H20: 1 | J20: 1 | K20: U | L20: 1 | M20: 1 | N20: 1 | P20: 1 | Q20: 1 | R20: 1 | S20: 1 | T20: 1 | AB20: {=COUNTIF(D20:Z20,1)+COUNTIF(D20:Z20,U)+COUNTIF(D20:Z20,_xleta.T)+COUNTIF(D20:Z20,J)} -> 13 | AC20: =COUNTIF(D20:Z20,0) -> 0 | AD20: =COUNTIF(D20:Z20,"T") -> 0 | AE20: =COUNTIF(D20:Z20,"U") -> 2 | AF20: =COUNTIF(D20:Z20,"J") -> 0 | AG20: =SUM(AB20)/20 -> 0.65
A21: 10 | B21: =Enero!B21 -> 7 | C21: =Enero!C21 -> Rodríguez Correa Dubian Esteban | D21: 1 | E21: 1 | F21: 1 | G21: 1 | H21: 1 | J21: 1 | K21: 1 | L21: 1 | M21: 1 | N21: 1 | P21: 1 | Q21: 1 | R21: 1 | S21: 1 | T21: 1 | AB21: {=COUNTIF(D21:Z21,1)+COUNTIF(D21:Z21,U)+COUNTIF(D21:Z21,_xleta.T)+COUNTIF(D21:Z21,J)} -> 15 | AC21: =COUNTIF(D21:Z21,0) -> 0 | AD21: =COUNTIF(D21:Z21,"T") -> 0 | AE21: =COUNTIF(D21:Z21,"U") -> 0 | AF21: =COUNTIF(D21:Z21,"J") -> 0 | AG21: =SUM(AB21)/20 -> 0.75
A22: 11 | B22: =Enero!B22 -> 7 | C22: =Enero!C22 -> Valencia Virgen Alexandra | D22: 1 | E22: 1 | F22: U | G22: 1 | H22: 1 | J22: 0 | K22: U | L22: 1 | M22: 1 | N22: 1 | P22: 1 | Q22: 1 | R22: 1 | S22: U | T22: 1 | AB22: {=COUNTIF(D22:Z22,1)+COUNTIF(D22:Z22,U)+COUNTIF(D22:Z22,_xleta.T)+COUNTIF(D22:Z22,J)} -> 11 | AC22: =COUNTIF(D22:Z22,0) -> 1 | AD22: =COUNTIF(D22:Z22,"T") -> 0 | AE22: =COUNTIF(D22:Z22,"U") -> 3 | AF22: =COUNTIF(D22:Z22,"J") -> 0 | AG22: =SUM(AB22)/20 -> 0.55
A23: 12 | B23: =Enero!B23 -> 8 | C23: =Enero!C23 -> Caviedes Hernández Juan Manuel | D23: 1 | E23: 1 | F23: 1 | G23: 1 | H23: 1 | J23: 1 | K23: 1 | L23: 1 | M23: 1 | N23: 1 | P23: 1 | Q23: 1 | R23: 1 | S23: 1 | T23: 1 | AB23: {=COUNTIF(D23:Z23,1)+COUNTIF(D23:Z23,U)+COUNTIF(D23:Z23,_xleta.T)+COUNTIF(D23:Z23,J)} -> 15 | AC23: =COUNTIF(D23:Z23,0) -> 0 | AD23: =COUNTIF(D23:Z23,"T") -> 0 | AE23: =COUNTIF(D23:Z23,"U") -> 0 | AF23: =COUNTIF(D23:Z23,"J") -> 0 | AG23: =SUM(AB23)/20 -> 0.75
A24: 13 | B24: =Enero!B24 -> 8 | C24: =Enero!C24 -> Orozco Chavarría Cristóbal | D24: T | E24: 1 | F24: 1 | G24: 1 | H24: 1 | J24: 1 | K24: 1 | L24: 0 | M24: 1 | N24: 1 | P24: 1 | Q24: 1 | R24: U | S24: 1 | T24: 1 | AB24: {=COUNTIF(D24:Z24,1)+COUNTIF(D24:Z24,U)+COUNTIF(D24:Z24,_xleta.T)+COUNTIF(D24:Z24,J)} -> 12 | AC24: =COUNTIF(D24:Z24,0) -> 1 | AD24: =COUNTIF(D24:Z24,"T") -> 0 | AE24: =COUNTIF(D24:Z24,"U") -> 1 | AF24: =COUNTIF(D24:Z24,"J") -> 0 | AG24: =SUM(AB24)/20 -> 0.6
A25: 14 | B25: =Enero!B25 -> 8 | C25: =Enero!C25 -> Velásquez Muñoz Anyely Tatiana | D25: 1 | E25: 1 | F25: 1 | G25: 1 | H25: 1 | J25: 1 | K25: 1 | L25: 1 | M25: 1 | N25: 1 | P25: 1 | Q25: 1 | R25: 1 | S25: 1 | T25: 1 | AB25: {=COUNTIF(D25:Z25,1)+COUNTIF(D25:Z25,U)+COUNTIF(D25:Z25,_xleta.T)+COUNTIF(D25:Z25,J)} -> 15 | AC25: =COUNTIF(D25:Z25,0) -> 0 | AD25: =COUNTIF(D25:Z25,"T") -> 0 | AE25: =COUNTIF(D25:Z25,"U") -> 0 | AF25: =COUNTIF(D25:Z25,"J") -> 0 | AG25: =SUM(AB25)/20 -> 0.75
A26: 15 | B26: =Enero!B26 -> 9 | C26: =Enero!C26 -> Dávila Bedoya Evelin Sofía | D26: 1 | E26: 1 | F26: 1 | G26: 1 | H26: 1 | J26: 1 | K26: 1 | L26: 1 | M26: 1 | N26: 1 | P26: 1 | Q26: 1 | R26: 1 | S26: 1 | T26: 1 | AB26: {=COUNTIF(D26:Z26,1)+COUNTIF(D26:Z26,U)+COUNTIF(D26:Z26,_xleta.T)+COUNTIF(D26:Z26,J)} -> 15 | AC26: =COUNTIF(D26:Z26,0) -> 0 | AD26: =COUNTIF(D26:Z26,"T") -> 0 | AE26: =COUNTIF(D26:Z26,"U") -> 0 | AF26: =COUNTIF(D26:Z26,"J") -> 0 | AG26: =SUM(AB26)/20 -> 0.75
A27: 16 | B27: =Enero!B27 -> 9 | C27: =Enero!C27 -> Duque Aristizabal Ángel Gabriel | D27: 1 | E27: 1 | F27: U | G27: 1 | H27: 1 | J27: 1 | K27: 1 | L27: 1 | M27: 1 | N27: 1 | P27: 1 | Q27: 1 | R27: 1 | S27: 1 | T27: 1 | AB27: {=COUNTIF(D27:Z27,1)+COUNTIF(D27:Z27,U)+COUNTIF(D27:Z27,_xleta.T)+COUNTIF(D27:Z27,J)} -> 14 | AC27: =COUNTIF(D27:Z27,0) -> 0 | AD27: =COUNTIF(D27:Z27,"T") -> 0 | AE27: =COUNTIF(D27:Z27,"U") -> 1 | AF27: =COUNTIF(D27:Z27,"J") -> 0 | AG27: =SUM(AB27)/20 -> 0.7
A28: 17 | B28: =Enero!B28 -> 9 | C28: =Enero!C28 -> Eusse Castañeda María Fernanda | D28: 1 | E28: 1 | F28: 1 | G28: 1 | H28: 1 | J28: 1 | K28: 1 | L28: 1 | M28: 1 | N28: 1 | P28: 1 | Q28: 1 | R28: 1 | S28: 1 | T28: 1 | AB28: {=COUNTIF(D28:Z28,1)+COUNTIF(D28:Z28,U)+COUNTIF(D28:Z28,_xleta.T)+COUNTIF(D28:Z28,J)} -> 15 | AC28: =COUNTIF(D28:Z28,0) -> 0 | AD28: =COUNTIF(D28:Z28,"T") -> 0 | AE28: =COUNTIF(D28:Z28,"U") -> 0 | AF28: =COUNTIF(D28:Z28,"J") -> 0 | AG28: =SUM(AB28)/20 -> 0.75
A29: 18 | B29: =Enero!B29 -> 9 | C29: =Enero!C29 -> Franco Barraza Gyshet Johanna | D29: 1 | E29: 1 | F29: 1 | G29: 1 | H29: 1 | J29: 1 | K29: 1 | L29: U | M29: 1 | N29: 1 | P29: 1 | Q29: 1 | R29: 1 | S29: 1 | T29: 1 | AB29: {=COUNTIF(D29:Z29,1)+COUNTIF(D29:Z29,U)+COUNTIF(D29:Z29,_xleta.T)+COUNTIF(D29:Z29,J)} -> 14 | AC29: =COUNTIF(D29:Z29,0) -> 0 | AD29: =COUNTIF(D29:Z29,"T") -> 0 | AE29: =COUNTIF(D29:Z29,"U") -> 1 | AF29: =COUNTIF(D29:Z29,"J") -> 0 | AG29: =SUM(AB29)/20 -> 0.7
A30: 19 | B30: =Enero!B30 -> 9 | C30: =Enero!C30 -> Giraldo Giraldo Juan Camilo | D30: 1 | E30: 1 | F30: 1 | G30: 1 | H30: 1 | J30: 1 | K30: 1 | L30: 1 | M30: 1 | N30: 1 | P30: 1 | Q30: U | R30: 1 | S30: 1 | T30: 1 | AB30: {=COUNTIF(D30:Z30,1)+COUNTIF(D30:Z30,U)+COUNTIF(D30:Z30,_xleta.T)+COUNTIF(D30:Z30,J)} -> 14 | AC30: =COUNTIF(D30:Z30,0) -> 0 | AD30: =COUNTIF(D30:Z30,"T") -> 0 | AE30: =COUNTIF(D30:Z30,"U") -> 1 | AF30: =COUNTIF(D30:Z30,"J") -> 0 | AG30: =SUM(AB30)/20 -> 0.7
A31: 20 | B31: =Enero!B31 -> 9 | C31: =Enero!C31 -> Gómez Vergara Michael Estiven | D31: 1 | E31: 1 | F31: 1 | G31: 1 | H31: 1 | J31: 1 | K31: 1 | L31: 1 | M31: 1 | N31: 1 | P31: 1 | Q31: 1 | R31: 1 | S31: 1 | T31: 1 | AB31: {=COUNTIF(D31:Z31,1)+COUNTIF(D31:Z31,U)+COUNTIF(D31:Z31,_xleta.T)+COUNTIF(D31:Z31,J)} -> 15 | AC31: =COUNTIF(D31:Z31,0) -> 0 | AD31: =COUNTIF(D31:Z31,"T") -> 0 | AE31: =COUNTIF(D31:Z31,"U") -> 0 | AF31: =COUNTIF(D31:Z31,"J") -> 0 | AG31: =SUM(AB31)/20 -> 0.75
A32: 21 | B32: =Enero!B32 -> 9 | C32: =Enero!C32 -> López Aguirre Alexis | D32: 0 | E32: 1 | F32: 1 | G32: 1 | H32: 1 | J32: 1 | K32: 1 | L32: 1 | M32: 1 | N32: 1 | P32: J | Q32: 1 | R32: 1 | S32: 1 | T32: 1 | AB32: {=COUNTIF(D32:Z32,1)+COUNTIF(D32:Z32,U)+COUNTIF(D32:Z32,_xleta.T)+COUNTIF(D32:Z32,J)} -> 13 | AC32: =COUNTIF(D32:Z32,0) -> 1 | AD32: =COUNTIF(D32:Z32,"T") -> 0 | AE32: =COUNTIF(D32:Z32,"U") -> 0 | AF32: =COUNTIF(D32:Z32,"J") -> 1 | AG32: =SUM(AB32)/20 -> 0.65
A33: 22 | B33: =Enero!B33 -> 10 | C33: =Enero!C33 -> Duque Aristizabal Yennifer | D33: 1 | E33: 1 | F33: 1 | G33: 1 | H33: 1 | J33: 1 | K33: 1 | L33: 1 | M33: 1 | N33: 1 | P33: 1 | Q33: 1 | R33: 1 | S33: 1 | T33: 1 | AB33: {=COUNTIF(D33:Z33,1)+COUNTIF(D33:Z33,U)+COUNTIF(D33:Z33,_xleta.T)+COUNTIF(D33:Z33,J)} -> 15 | AC33: =COUNTIF(D33:Z33,0) -> 0 | AD33: =COUNTIF(D33:Z33,"T") -> 0 | AE33: =COUNTIF(D33:Z33,"U") -> 0 | AF33: =COUNTIF(D33:Z33,"J") -> 0 | AG33: =SUM(AB33)/20 -> 0.75
A34: 23 | B34: =Enero!B34 -> 10 | C34: =Enero!C34 -> García Navarro Sebastian Camilo | D34: 1 | E34: 1 | F34: 1 | G34: 1 | H34: 1 | J34: 1 | K34: 1 | L34: 1 | M34: 1 | N34: 1 | P34: 1 | Q34: 1 | R34: 1 | S34: 1 | T34: 1 | AB34: {=COUNTIF(D34:Z34,1)+COUNTIF(D34:Z34,U)+COUNTIF(D34:Z34,_xleta.T)+COUNTIF(D34:Z34,J)} -> 15 | AC34: =COUNTIF(D34:Z34,0) -> 0 | AD34: =COUNTIF(D34:Z34,"T") -> 0 | AE34: =COUNTIF(D34:Z34,"U") -> 0 | AF34: =COUNTIF(D34:Z34,"J") -> 0 | AG34: =SUM(AB34)/20 -> 0.75
A35: 24 | B35: =Enero!B35 -> 10 | C35: =Enero!C35 -> Gallego Giraldo Marlon | D35: 1 | E35: 1 | F35: 1 | G35: 1 | H35: 1 | J35: 1 | K35: 1 | L35: 1 | M35: 1 | N35: 1 | P35: 1 | Q35: 1 | R35: 1 | S35: 1 | T35: 1 | AB35: {=COUNTIF(D35:Z35,1)+COUNTIF(D35:Z35,U)+COUNTIF(D35:Z35,_xleta.T)+COUNTIF(D35:Z35,J)} -> 15 | AC35: =COUNTIF(D35:Z35,0) -> 0 | AD35: =COUNTIF(D35:Z35,"T") -> 0 | AE35: =COUNTIF(D35:Z35,"U") -> 0 | AF35: =COUNTIF(D35:Z35,"J") -> 0 | AG35: =SUM(AB35)/20 -> 0.75
A36: 25 | B36: =Enero!B36 -> 10 | C36: =Enero!C36 -> Gómez Pamplona Julieta | D36: 1 | E36: 1 | F36: 1 | G36: 1 | H36: 1 | J36: 1 | K36: 1 | L36: 1 | M36: 1 | N36: 1 | P36: J | Q36: 1 | R36: 1 | S36: 1 | T36: 1 | AB36: {=COUNTIF(D36:Z36,1)+COUNTIF(D36:Z36,U)+COUNTIF(D36:Z36,_xleta.T)+COUNTIF(D36:Z36,J)} -> 14 | AC36: =COUNTIF(D36:Z36,0) -> 0 | AD36: =COUNTIF(D36:Z36,"T") -> 0 | AE36: =COUNTIF(D36:Z36,"U") -> 0 | AF36: =COUNTIF(D36:Z36,"J") -> 1 | AG36: =SUM(AB36)/20 -> 0.7
A37: 26 | B37: =Enero!B37 -> 10 | C37: =Enero!C37 -> González Martínez Salomé | D37: J | E37: 1 | F37: 1 | G37: 1 | H37: 1 | J37: 1 | K37: 1 | L37: 1 | M37: 1 | N37: 1 | P37: 1 | Q37: 1 | R37: 1 | S37: 1 | T37: 1 | AB37: {=COUNTIF(D37:Z37,1)+COUNTIF(D37:Z37,U)+COUNTIF(D37:Z37,_xleta.T)+COUNTIF(D37:Z37,J)} -> 14 | AC37: =COUNTIF(D37:Z37,0) -> 0 | AD37: =COUNTIF(D37:Z37,"T") -> 0 | AE37: =COUNTIF(D37:Z37,"U") -> 0 | AF37: =COUNTIF(D37:Z37,"J") -> 1 | AG37: =SUM(AB37)/20 -> 0.7
A38: 27 | B38: 10 | C38: Lezcano Morillo Edwin Alexander | D38: J | E38: J | F38: 1 | G38: 1 | H38: 1 | J38: 1 | K38: 1 | L38: 1 | M38: 1 | N38: 1 | P38: 1 | Q38: 1 | R38: 1 | S38: 1 | T38: 1 | AB38: {=COUNTIF(D38:Z38,1)+COUNTIF(D38:Z38,U)+COUNTIF(D38:Z38,_xleta.T)+COUNTIF(D38:Z38,J)} -> 13 | AC38: =COUNTIF(D38:Z38,0) -> 0 | AD38: =COUNTIF(D38:Z38,"T") -> 0 | AE38: =COUNTIF(D38:Z38,"U") -> 0 | AF38: =COUNTIF(D38:Z38,"J") -> 2 | AG38: =SUM(AB38)/20 -> 0.65
A39: 28 | B39: =Enero!B39 -> 10 | C39: =Enero!C39 -> Valencia Vásquez Anderson | D39: 1 | E39: 1 | F39: 1 | G39: U | H39: 1 | J39: 1 | K39: 1 | L39: 1 | M39: 1 | N39: 1 | P39: J | Q39: 1 | R39: 1 | S39: 1 | T39: 1 | AB39: {=COUNTIF(D39:Z39,1)+COUNTIF(D39:Z39,U)+COUNTIF(D39:Z39,_xleta.T)+COUNTIF(D39:Z39,J)} -> 13 | AC39: =COUNTIF(D39:Z39,0) -> 0 | AD39: =COUNTIF(D39:Z39,"T") -> 0 | AE39: =COUNTIF(D39:Z39,"U") -> 1 | AF39: =COUNTIF(D39:Z39,"J") -> 1 | AG39: =SUM(AB39+AD39)/20 -> 0.65
A40: 29 | B40: =Enero!B40 -> 11 | C40: =Enero!C40 -> Caviedes Hernández Cristina | D40: 1 | E40: 1 | F40: 1 | G40: 1 | H40: 1 | J40: 1 | K40: 1 | L40: 1 | M40: 1 | N40: 1 | P40: 1 | Q40: 1 | R40: 1 | S40: 1 | T40: 1 | AB40: {=COUNTIF(D40:Z40,1)+COUNTIF(D40:Z40,U)+COUNTIF(D40:Z40,_xleta.T)+COUNTIF(D40:Z40,J)} -> 15 | AC40: =COUNTIF(D40:Z40,0) -> 0 | AD40: =COUNTIF(D40:Z40,"T") -> 0 | AE40: =COUNTIF(D40:Z40,"U") -> 0 | AF40: =COUNTIF(D40:Z40,"J") -> 0 | AG40: =SUM(AB40+AD40)/20 -> 0.75

Sheet Marzo
C2: #VALUE! | AA2: Código: IERLJ_AE_06
AA4: Página: 1 de 1
AA6: Versión: 1.0
C7: SEGUIMIENTO A LA ASISTENCIA
A9: Docente: | H9: Sede | T9: Área/Asignaura
A10: Sede | K10: Mes | AA10: Año
A11: N° | B11: GRADO | C11: NOMBRES Y APELLIDOS | D11: 2 | E11: 3 | F11: 4 | G11: 5 | H11: 6 | J11: 9 | K11: 10 | L11: 11 | M11: 12 | N11: 13 | P11: 16 | Q11: 17 | R11: 18 | S11: 19 | T11: 20 | V11: 24 | W11: 25 | X11: 26 | Y11: 27 | AA11: ASISTENCIA | AB11: FALTAS | AC11: TARDE | AD11: UNIFORME | AE11: JUSTIFICACIÓN | AF11: % ASISTENCIA | AI11: VALORES PARA LLENAR LA ASISTENCIA
A12: 1 | B12: 6 | C12: Barrientos Gallo Juan Sebastian | D12: 1 | E12: 1 | F12: 1 | AA12: {=COUNTIF(D12:Y12,1)+COUNTIF(D12:Y12,_xleta.T)+COUNTIF(D12:Y12,U)+COUNTIF(D12:Y12,J)} -> 3 | AB12: =COUNTIF(D12:Y12,0) -> 0 | AC12: =COUNTIF(D12:Y12,"T") -> 0 | AD12: =COUNTIF(D12:Y12,"U") -> 0 | AE12: =COUNTIF(D12:Y12,"J") -> 0 | AF12: =SUM(AA12)/COUNTA($D$11:$H$11,$J$11:$N$11,$P$11:$T$11,$V$11:$Y$11) -> 0.15789474 | AJ12: 1 | AK12: Asistio
A13: 2 | B13: =Enero!B13 -> 6 | C13: =Enero!C13 -> Dávila Bedoya Kevin Alejandro | D13: 1 | E13: 1 | F13: U | AA13: {=COUNTIF(D13:Y13,1)+COUNTIF(D13:Y13,_xleta.T)+COUNTIF(D13:Y13,U)+COUNTIF(D13:Y13,J)} -> 2 | AB13: =COUNTIF(D13:Y13,0) -> 0 | AC13: =COUNTIF(D13:Y13,"T") -> 0 | AD13: =COUNTIF(D13:Y13,"U") -> 1 | AE13: =COUNTIF(D13:Y13,"J") -> 0 | AF13: =SUM(AA13)/COUNTA($D$11:$H$11,$J$11:$N$11,$P$11:$T$11,$V$11:$Y$11) -> 0.10526316 | AJ13: 0 | AK13: No asistio (faltas)
A14: 3 | B14: =Enero!B14 -> 6 | C14: =Enero!C14 -> Franco Barraza Maria Jose | D14: 1 | E14: 1 | F14: 1 | AA14: {=COUNTIF(D14:Y14,1)+COUNTIF(D14:Y14,_xleta.T)+COUNTIF(D14:Y14,U)+COUNTIF(D14:Y14,J)} -> 3 | AB14: =COUNTIF(D14:Y14,0) -> 0 | AC14: =COUNTIF(D14:Y14,"T") -> 0 | AD14: =COUNTIF(D14:Y14,"U") -> 0 | AE14: =COUNTIF(D14:Y14,"J") -> 0 | AF14: =SUM(AA14)/COUNTA($D$11:$H$11,$J$11:$N$11,$P$11:$T$11,$V$11:$Y$11) -> 0.15789474 | AJ14: T | AK14: Llegada tarde
A15: 4 | B15: =Enero!B15 -> 6 | C15: =Enero!C15 -> Vera Figuera Branyelis Del Carmen | D15: 1 | E15: 1 | AA15: {=COUNTIF(D15:Y15,1)+COUNTIF(D15:Y15,_xleta.T)+COUNTIF(D15:Y15,U)+COUNTIF(D15:Y15,J)} -> 2 | AB15: =COUNTIF(D15:Y15,0) -> 0 | AC15: =COUNTIF(D15:Y15,"T") -> 0 | AD15: =COUNTIF(D15:Y15,"U") -> 0 | AE15: =COUNTIF(D15:Y15,"J") -> 0 | AF15: =SUM(AA15)/COUNTA($D$11:$H$11,$J$11:$N$11,$P$11:$T$11,$V$11:$Y$11) -> 0.10526316 | AJ15: J | AK15: Justificación
A16: 5 | B16: =Enero!B16 -> 7 | C16: =Enero!C16 -> Adrianza Figuera Brainer Josué | D16: 1 | E16: 1 | AA16: {=COUNTIF(D16:Y16,1)+COUNTIF(D16:Y16,_xleta.T)+COUNTIF(D16:Y16,U)+COUNTIF(D16:Y16,J)} -> 2 | AB16: =COUNTIF(D16:Y16,0) -> 0 | AC16: =COUNTIF(D16:Y16,"T") -> 0 | AD16: =COUNTIF(D16:Y16,"U") -> 0 | AE16: =COUNTIF(D16:Y16,"J") -> 0 | AF16: =SUM(AA16)/COUNTA($D$11:$H$11,$J$11:$N$11,$P$11:$T$11,$V$11:$Y$11) -> 0.10526316 | AJ16: U | AK16: Uniforme
A17: 6 | B17: =Enero!B17 -> 7 | C17: =Enero!C17 -> Chavarría Valencia Dylan Alexis | D17: 1 | E17: 1 | AA17: {=COUNTIF(D17:Y17,1)+COUNTIF(D17:Y17,_xleta.T)+COUNTIF(D17:Y17,U)+COUNTIF(D17:Y17,J)} -> 2 | AB17: =COUNTIF(D17:Y17,0) -> 0 | AC17: =COUNTIF(D17:Y17,"T") -> 0 | AD17: =COUNTIF(D17:Y17,"U") -> 0 | AE17: =COUNTIF(D17:Y17,"J") -> 0 | AF17: =SUM(AA17)/COUNTA($D$11:$H$11,$J$11:$N$11,$P$11:$T$11,$V$11:$Y$11) -> 0.10526316
A18: 7 | B18: =Enero!B18 -> 7 | C18: =Enero!C18 -> Giraldo Ceballos Miguel Angel | D18: J | E18: J | AA18: {=COUNTIF(D18:Y18,1)+COUNTIF(D18:Y18,_xleta.T)+COUNTIF(D18:Y18,U)+COUNTIF(D18:Y18,J)} -> 0 | AB18: =COUNTIF(D18:Y18,0) -> 0 | AC18: =COUNTIF(D18:Y18,"T") -> 0 | AD18: =COUNTIF(D18:Y18,"U") -> 0 | AE18: =COUNTIF(D18:Y18,"J") -> 2 | AF18: =SUM(AA18)/COUNTA($D$11:$H$11,$J$11:$N$11,$P$11:$T$11,$V$11:$Y$11) -> 0
A19: 8 | B19: =Enero!B19 -> 7 | C19: =Enero!C19 -> Hincapié Muñoz Juan Pablo | D19: 1 | E19: 1 | AA19: {=COUNTIF(D19:Y19,1)+COUNTIF(D19:Y19,_xleta.T)+COUNTIF(D19:Y19,U)+COUNTIF(D19:Y19,J)} -> 2 | AB19: =COUNTIF(D19:Y19,0) -> 0 | AC19: =COUNTIF(D19:Y19,"T") -> 0 | AD19: =COUNTIF(D19:Y19,"U") -> 0 | AE19: =COUNTIF(D19:Y19,"J") -> 0 | AF19: =SUM(AA19)/COUNTA($D$11:$H$11,$J$11:$N$11,$P$11:$T$11,$V$11:$Y$11) -> 0.10526316
A20: 9 | B20: =Enero!B20 -> 7 | C20: =Enero!C20 -> Jiménez Muñoz Alejandro | D20: 1 | E20: 1 | AA20: {=COUNTIF(D20:Y20,1)+COUNTIF(D20:Y20,_xleta.T)+COUNTIF(D20:Y20,U)+COUNTIF(D20:Y20,J)} -> 2 | AB20: =COUNTIF(D20:Y20,0) -> 0 | AC20: =COUNTIF(D20:Y20,"T") -> 0 | AD20: =COUNTIF(D20:Y20,"U") -> 0 | AE20: =COUNTIF(D20:Y20,"J") -> 0 | AF20: =SUM(AA20)/COUNTA($D$11:$H$11,$J$11:$N$11,$P$11:$T$11,$V$11:$Y$11) -> 0.10526316
A21: 10 | B21: =Enero!B21 -> 7 | C21: =Enero!C21 -> Rodríguez Correa Dubian Esteban | D21: 1 | E21: 1 | AA21: {=COUNTIF(D21:Y21,1)+COUNTIF(D21:Y21,_xleta.T)+COUNTIF(D21:Y21,U)+COUNTIF(D21:Y21,J)} -> 2 | AB21: =COUNTIF(D21:Y21,0) -> 0 | AC21: =COUNTIF(D21:Y21,"T") -> 0 | AD21: =COUNTIF(D21:Y21,"U") -> 0 | AE21: =COUNTIF(D21:Y21,"J") -> 0 | AF21: =SUM(AA21)/COUNTA($D$11:$H$11,$J$11:$N$11,$P$11:$T$11,$V$11:$Y$11) -> 0.10526316
A22: 11 | B22: =Enero!B22 -> 7 | C22: =Enero!C22 -> Valencia Virgen Alexandra | D22: 1 | E22: 1 | AA22: {=COUNTIF(D22:Y22,1)+COUNTIF(D22:Y22,_xleta.T)+COUNTIF(D22:Y22,U)+COUNTIF(D22:Y22,J)} -> 2 | AB22: =COUNTIF(D22:Y22,0) -> 0 | AC22: =COUNTIF(D22:Y22,"T") -> 0 | AD22: =COUNTIF(D22:Y22,"U") -> 0 | AE22: =COUNTIF(D22:Y22,"J") -> 0 | AF22: =SUM(AA22)/COUNTA($D$11:$H$11,$J$11:$N$11,$P$11:$T$11,$V$11:$Y$11) -> 0.10526316
A23: 12 | B23: =Enero!B23 -> 8 | C23: =Enero!C23 -> Caviedes Hernández Juan Manuel | D23: 1 | E23: 1 | AA23: {=COUNTIF(D23:Y23,1)+COUNTIF(D23:Y23,_xleta.T)+COUNTIF(D23:Y23,U)+COUNTIF(D23:Y23,J)} -> 2 | AB23: =COUNTIF(D23:Y23,0) -> 0 | AC23: =COUNTIF(D23:Y23,"T") -> 0 | AD23: =COUNTIF(D23:Y23,"U") -> 0 | AE23: =COUNTIF(D23:Y23,"J") -> 0 | AF23: =SUM(AA23)/COUNTA($D$11:$H$11,$J$11:$N$11,$P$11:$T$11,$V$11:$Y$11) -> 0.10526316
A24: 13 | B24: =Enero!B24 -> 8 | C24: =Enero!C24 -> Orozco Chavarría Cristóbal | D24: J | E24: J | AA24: {=COUNTIF(D24:Y24,1)+COUNTIF(D24:Y24,_xleta.T)+COUNTIF(D24:Y24,U)+COUNTIF(D24:Y24,J)} -> 0 | AB24: =COUNTIF(D24:Y24,0) -> 0 | AC24: =COUNTIF(D24:Y24,"T") -> 0 | AD24: =COUNTIF(D24:Y24,"U") -> 0 | AE24: =COUNTIF(D24:Y24,"J") -> 2 | AF24: =SUM(AA24)/COUNTA($D$11:$H$11,$J$11:$N$11,$P$11:$T$11,$V$11:$Y$11) -> 0
A25: 14 | B25: =Enero!B25 -> 8 | C25: =Enero!C25 -> Velásquez Muñoz Anyely Tatiana | D25: 0 | E25: 1 | AA25: {=COUNTIF(D25:Y25,1)+COUNTIF(D25:Y25,_xleta.T)+COUNTIF(D25:Y25,U)+COUNTIF(D25:Y25,J)} -> 1 | AB25: =COUNTIF(D25:Y25,0) -> 1 | AC25: =COUNTIF(D25:Y25,"T") -> 0 | AD25: =COUNTIF(D25:Y25,"U") -> 0 | AE25: =COUNTIF(D25:Y25,"J") -> 0 | AF25: =SUM(AA25)/COUNTA($D$11:$H$11,$J$11:$N$11,$P$11:$T$11,$V$11:$Y$11) -> 0.052631579
A26: 15 | B26: =Enero!B26 -> 9 | C26: =Enero!C26 -> Dávila Bedoya Evelin Sofía | D26: 1 | E26: 1 | AA26: {=COUNTIF(D26:Y26,1)+COUNTIF(D26:Y26,_xleta.T)+COUNTIF(D26:Y26,U)+COUNTIF(D26:Y26,J)} -> 2 | AB26: =COUNTIF(D26:Y26,0) -> 0 | AC26: =COUNTIF(D26:Y26,"T") -> 0 | AD26: =COUNTIF(D26:Y26,"U") -> 0 | AE26: =COUNTIF(D26:Y26,"J") -> 0 | AF26: =SUM(AA26)/COUNTA($D$11:$H$11,$J$11:$N$11,$P$11:$T$11,$V$11:$Y$11) -> 0.10526316
A27: 16 | B27: =Enero!B27 -> 9 | C27: =Enero!C27 -> Duque Aristizabal Ángel Gabriel | D27: 0 | E27: 1 | AA27: {=COUNTIF(D27:Y27,1)+COUNTIF(D27:Y27,_xleta.T)+COUNTIF(D27:Y27,U)+COUNTIF(D27:Y27,J)} -> 1 | AB27: =COUNTIF(D27:Y27,0) -> 1 | AC27: =COUNTIF(D27:Y27,"T") -> 0 | AD27: =COUNTIF(D27:Y27,"U") -> 0 | AE27: =COUNTIF(D27:Y27,"J") -> 0 | AF27: =SUM(AA27)/COUNTA($D$11:$H$11,$J$11:$N$11,$P$11:$T$11,$V$11:$Y$11) -> 0.052631579
A28: 17 | B28: =Enero!B28 -> 9 | C28: =Enero!C28 -> Eusse Castañeda María Fernanda | D28: 1 | E28: 1 | AA28: {=COUNTIF(D28:Y28,1)+COUNTIF(D28:Y28,_xleta.T)+COUNTIF(D28:Y28,U)+COUNTIF(D28:Y28,J)} -> 2 | AB28: =COUNTIF(D28:Y28,0) -> 0 | AC28: =COUNTIF(D28:Y28,"T") -> 0 | AD28: =COUNTIF(D28:Y28,"U") -> 0 | AE28: =COUNTIF(D28:Y28,"J") -> 0 | AF28: =SUM(AA28)/COUNTA($D$11:$H$11,$J$11:$N$11,$P$11:$T$11,$V$11:$Y$11) -> 0.10526316
A29: 18 | B29: =Enero!B29 -> 9 | C29: =Enero!C29 -> Franco Barraza Gyshet Johanna | D29: 1 | E29: 1 | AA29: {=COUNTIF(D29:Y29,1)+COUNTIF(D29:Y29,_xleta.T)+COUNTIF(D29:Y29,U)+COUNTIF(D29:Y29,J)} -> 2 | AB29: =COUNTIF(D29:Y29,0) -> 0 | AC29: =COUNTIF(D29:Y29,"T") -> 0 | AD29: =COUNTIF(D29:Y29,"U") -> 0 | AE29: =COUNTIF(D29:Y29,"J") -> 0 | AF29: =SUM(AA29)/COUNTA($D$11:$H$11,$J$11:$N$11,$P$11:$T$11,$V$11:$Y$11) -> 0.10526316
A30: 19 | B30: =Enero!B30 -> 9 | C30: =Enero!C30 -> Giraldo Giraldo Juan Camilo | D30: 1 | E30: 1 | AA30: {=COUNTIF(D30:Y30,1)+COUNTIF(D30:Y30,_xleta.T)+COUNTIF(D30:Y30,U)+COUNTIF(D30:Y30,J)} -> 2 | AB30: =COUNTIF(D30:Y30,0) -> 0 | AC30: =COUNTIF(D30:Y30,"T") -> 0 | AD30: =COUNTIF(D30:Y30,"U") -> 0 | AE30: =COUNTIF(D30:Y30,"J") -> 0 | AF30: =SUM(AA30)/COUNTA($D$11:$H$11,$J$11:$N$11,$P$11:$T$11,$V$11:$Y$11) -> 0.10526316
A31: 20 | B31: =Enero!B31 -> 9 | C31: =Enero!C31 -> Gómez Vergara Michael Estiven | D31: 1 | E31: 0 | AA31: {=COUNTIF(D31:Y31,1)+COUNTIF(D31:Y31,_xleta.T)+COUNTIF(D31:Y31,U)+COUNTIF(D31:Y31,J)} -> 1 | AB31: =COUNTIF(D31:Y31,0) -> 1 | AC31: =COUNTIF(D31:Y31,"T") -> 0 | AD31: =COUNTIF(D31:Y31,"U") -> 0 | AE31: =COUNTIF(D31:Y31,"J") -> 0 | AF31: =SUM(AA31)/COUNTA($D$11:$H$11,$J$11:$N$11,$P$11:$T$11,$V$11:$Y$11) -> 0.052631579
A32: 21 | B32: =Enero!B32 -> 9 | C32: =Enero!C32 -> López Aguirre Alexis | D32: 1 | E32: 1 | AA32: {=COUNTIF(D32:Y32,1)+COUNTIF(D32:Y32,_xleta.T)+COUNTIF(D32:Y32,U)+COUNTIF(D32:Y32,J)} -> 2 | AB32: =COUNTIF(D32:Y32,0) -> 0 | AC32: =COUNTIF(D32:Y32,"T") -> 0 | AD32: =COUNTIF(D32:Y32,"U") -> 0 | AE32: =COUNTIF(D32:Y32,"J") -> 0 | AF32: =SUM(AA32)/COUNTA($D$11:$H$11,$J$11:$N$11,$P$11:$T$11,$V$11:$Y$11) -> 0.10526316
A33: 22 | B33: =Enero!B33 -> 10 | C33: =Enero!C33 -> Duque Aristizabal Yennifer | D33: 0 | E33: 1 | AA33: {=COUNTIF(D33:Y33,1)+COUNTIF(D33:Y33,_xleta.T)+COUNTIF(D33:Y33,U)+COUNTIF(D33:Y33,J)} -> 1 | AB33: =COUNTIF(D33:Y33,0) -> 1 | AC33: =COUNTIF(D33:Y33,"T") -> 0 | AD33: =COUNTIF(D33:Y33,"U") -> 0 | AE33: =COUNTIF(D33:Y33,"J") -> 0 | AF33: =SUM(AA33)/COUNTA($D$11:$H$11,$J$11:$N$11,$P$11:$T$11,$V$11:$Y$11) -> 0.052631579
A34: 23 | B34: =Enero!B34 -> 10 | C34: =Enero!C34 -> García Navarro Sebastian Camilo | D34: 1 | E34: 1 | AA34: {=COUNTIF(D34:Y34,1)+COUNTIF(D34:Y34,_xleta.T)+COUNTIF(D34:Y34,U)+COUNTIF(D34:Y34,J)} -> 2 | AB34: =COUNTIF(D34:Y34,0) -> 0 | AC34: =COUNTIF(D34:Y34,"T") -> 0 | AD34: =COUNTIF(D34:Y34,"U") -> 0 | AE34: =COUNTIF(D34:Y34,"J") -> 0 | AF34: =SUM(AA34)/COUNTA($D$11:$H$11,$J$11:$N$11,$P$11:$T$11,$V$11:$Y$11) -> 0.10526316
A35: 24 | B35: =Enero!B35 -> 10 | C35: =Enero!C35 -> Gallego Giraldo Marlon | D35: 1 | E35: 1 | AA35: {=COUNTIF(D35:Y35,1)+COUNTIF(D35:Y35,_xleta.T)+COUNTIF(D35:Y35,U)+COUNTIF(D35:Y35,J)} -> 2 | AB35: =COUNTIF(D35:Y35,0) -> 0 | AC35: =COUNTIF(D35:Y35,"T") -> 0 | AD35: =COUNTIF(D35:Y35,"U") -> 0 | AE35: =COUNTIF(D35:Y35,"J") -> 0 | AF35: =SUM(AA35)/COUNTA($D$11:$H$11,$J$11:$N$11,$P$11:$T$11,$V$11:$Y$11) -> 0.10526316
A36: 25 | B36: =Enero!B36 -> 10 | C36: =Enero!C36 -> Gómez Pamplona Julieta | D36: 1 | E36: 1 | AA36: {=COUNTIF(D36:Y36,1)+COUNTIF(D36:Y36,_xleta.T)+COUNTIF(D36:Y36,U)+COUNTIF(D36:Y36,J)} -> 2 | AB36: =COUNTIF(D36:Y36,0) -> 0 | AC36: =COUNTIF(D36:Y36,"T") -> 0 | AD36: =COUNTIF(D36:Y36,"U") -> 0 | AE36: =COUNTIF(D36:Y36,"J") -> 0 | AF36: =SUM(AA36)/COUNTA($D$11:$H$11,$J$11:$N$11,$P$11:$T$11,$V$11:$Y$11) -> 0.10526316
A37: 26 | B37: =Enero!B37 -> 10 | C37: =Enero!C37 -> González Martínez Salomé | D37: 1 | E37: 1 | AA37: {=COUNTIF(D37:Y37,1)+COUNTIF(D37:Y37,_xleta.T)+COUNTIF(D37:Y37,U)+COUNTIF(D37:Y37,J)} -> 2 | AB37: =COUNTIF(D37:Y37,0) -> 0 | AC37: =COUNTIF(D37:Y37,"T") -> 0 | AD37: =COUNTIF(D37:Y37,"U") -> 0 | AE37: =COUNTIF(D37:Y37,"J") -> 0 | AF37: =SUM(AA37)/COUNTA($D$11:$H$11,$J$11:$N$11,$P$11:$T$11,$V$11:$Y$11) -> 0.10526316
A38: 27 | B38: 10 | C38: Lezcano Morillo Edwin Alexander | D38: 1 | E38: 1 | AA38: {=COUNTIF(D38:Y38,1)+COUNTIF(D38:Y38,_xleta.T)+COUNTIF(D38:Y38,U)+COUNTIF(D38:Y38,J)} -> 2 | AB38: =COUNTIF(D38:Y38,0) -> 0 | AC38: =COUNTIF(D38:Y38,"T") -> 0 | AD38: =COUNTIF(D38:Y38,"U") -> 0 | AE38: =COUNTIF(D38:Y38,"J") -> 0 | AF38: =SUM(AA38)/COUNTA($D$11:$H$11,$J$11:$N$11,$P$11:$T$11,$V$11:$Y$11) -> 0.10526316
A39: 28 | B39: =Enero!B39 -> 10 | C39: =Enero!C39 -> Valencia Vásquez Anderson | D39: 1 | E39: 1 | AA39: {=COUNTIF(D39:Y39,1)+COUNTIF(D39:Y39,_xleta.T)+COUNTIF(D39:Y39,U)+COUNTIF(D39:Y39,J)} -> 2 | AB39: =COUNTIF(D39:Y39,0) -> 0 | AC39: =COUNTIF(D39:Y39,"T") -> 0 | AD39: =COUNTIF(D39:Y39,"U") -> 0 | AE39: =COUNTIF(D39:Y39,"J") -> 0 | AF39: =SUM(AA39)/COUNTA($D$11:$H$11,$J$11:$N$11,$P$11:$T$11,$V$11:$Y$11) -> 0.10526316
A40: 29 | B40: =Enero!B40 -> 11 | C40: =Enero!C40 -> Caviedes Hernández Cristina | D40: 1 | E40: 1 | AA40: {=COUNTIF(D40:Y40,1)+COUNTIF(D40:Y40,_xleta.T)+COUNTIF(D40:Y40,U)+COUNTIF(D40:Y40,J)} -> 2 | AB40: =COUNTIF(D40:Y40,0) -> 0 | AC40: =COUNTIF(D40:Y40,"T") -> 0 | AD40: =COUNTIF(D40:Y40,"U") -> 0 | AE40: =COUNTIF(D40:Y40,"J") -> 0 | AF40: =SUM(AA40)/COUNTA($D$11:$H$11,$J$11:$N$11,$P$11:$T$11,$V$11:$Y$11) -> 0.10526316

Sheet Abril
C2: #VALUE! | AA2: Código: IERLJ_AE_06
AA4: Página: 1 de 1
AA6: Versión: 1.0
C7: SEGUIMIENTO A LA ASISTENCIA
A9: Docente: | H9: Sede | T9: Área/Asignaura
A10: Sede | K10: Mes | AA10: Año
A11: N° | B11: GRADO | C11: NOMBRES Y APELLIDOS | D11: 6 | E11: 7 | F11: 8 | G11: 9 | H11: 10 | J11: 13 | K11: 14 | L11: 15 | M11: 16 | N11: 17 | P11: 20 | Q11: 21 | R11: 22 | S11: 23 | T11: 24 | V11: 27 | W11: 28 | X11: 29 | Y11: 30 | AA11: ASISTENCIA | AB11: FALTAS | AC11: TARDE | AD11: JUSTIFICACIÓN | AE11: % ASISTENCIA | AH11: VALORES PARA LLENAR LA ASISTENCIA
A12: 1 | B12: 6 | C12: Barrientos Gallo Juan Sebastian | D12: 1 | E12: 1 | F12: 1 | G12: 1 | H12: 1 | J12: 1 | K12: 1 | L12: 1 | M12: 1 | N12: 1 | P12: 1 | Q12: 1 | R12: 1 | S12: 1 | T12: 1 | V12: 1 | W12: 1 | X12: 1 | Y12: 1 | AA12: =COUNTIF(D12:Y12,1) -> 19 | AB12: =COUNTIF(D12:Y12,0) -> 0 | AC12: =COUNTIF(D12:Y12,"T") -> 0 | AD12: =COUNTIF(D12:Y12,"J") -> 0 | AE12: =SUM(AA12+AC12)/19 -> 1 | AI12: 1 | AJ12: Asistio
A13: 2 | B13: =Enero!B13 -> 6 | C13: =Enero!C13 -> Dávila Bedoya Kevin Alejandro | D13: 0 | E13: 0 | F13: 0 | G13: 0 | H13: 0 | J13: 0 | K13: 0 | L13: 0 | M13: 0 | N13: 0 | P13: 0 | Q13: 0 | R13: 0 | S13: 0 | T13: 0 | V13: 0 | W13: 0 | X13: 0 | Y13: 0 | AA13: =COUNTIF(D13:Y13,1) -> 0 | AB13: =COUNTIF(D13:Y13,0) -> 19 | AC13: =COUNTIF(D13:Y13,"T") -> 0 | AD13: =COUNTIF(D13:Y13,"J") -> 0 | AE13: =SUM(AA13+AC13)/19 -> 0 | AI13: 0 | AJ13: No asistio (faltas)
A14: 3 | B14: =Enero!B14 -> 6 | C14: =Enero!C14 -> Franco Barraza Maria Jose | D14: 1 | E14: 1 | F14: 1 | G14: 1 | H14: 1 | J14: 1 | K14: 1 | L14: 1 | M14: 1 | N14: 1 | P14: 1 | Q14: 1 | R14: 1 | S14: 1 | T14: 1 | V14: 1 | W14: 1 | X14: 1 | Y14: 1 | AA14: =COUNTIF(D14:Y14,1) -> 19 | AB14: =COUNTIF(D14:Y14,0) -> 0 | AC14: =COUNTIF(D14:Y14,"T") -> 0 | AD14: =COUNTIF(D14:Y14,"J") -> 0 | AE14: =SUM(AA14+AC14)/19 -> 1 | AI14: T | AJ14: Llegada tarde
A15: 4 | B15: =Enero!B15 -> 6 | C15: =Enero!C15 -> Vera Figuera Branyelis Del Carmen | D15: 1 | E15: 1 | F15: 1 | G15: 1 | H15: 1 | J15: 1 | K15: 1 | L15: 1 | M15: 1 | N15: 1 | P15: 1 | Q15: 1 | R15: 1 | S15: 1 | T15: 1 | V15: 1 | W15: 1 | X15: 1 | Y15: 1 | AA15: =COUNTIF(D15:Y15,1) -> 19 | AB15: =COUNTIF(D15:Y15,0) -> 0 | AC15: =COUNTIF(D15:Y15,"T") -> 0 | AD15: =COUNTIF(D15:Y15,"J") -> 0 | AE15: =SUM(AA15+AC15)/19 -> 1 | AI15: J | AJ15: Justificación
A16: 5 | B16: =Enero!B16 -> 7 | C16: =Enero!C16 -> Adrianza Figuera Brainer Josué | D16: 1 | E16: 1 | F16: 1 | G16: 1 | H16: 1 | J16: 1 | K16: 1 | L16: 1 | M16: 1 | N16: 1 | P16: 1 | Q16: 1 | R16: 1 | S16: 1 | T16: 1 | V16: 1 | W16: 1 | X16: 1 | Y16: 1 | AA16: =COUNTIF(D16:Y16,1) -> 19 | AB16: =COUNTIF(D16:Y16,0) -> 0 | AC16: =COUNTIF(D16:Y16,"T") -> 0 | AD16: =COUNTIF(D16:Y16,"J") -> 0 | AE16: =SUM(AA16+AC16)/19 -> 1
A17: 6 | B17: =Enero!B17 -> 7 | C17: =Enero!C17 -> Chavarría Valencia Dylan Alexis | D17: 1 | E17: 1 | F17: 1 | G17: 1 | H17: 1 | J17: 1 | K17: 1 | L17: 1 | M17: 1 | N17: 1 | P17: 1 | Q17: 1 | R17: 1 | S17: 1 | T17: 1 | V17: 1 | W17: 1 | X17: 1 | Y17: 1 | AA17: =COUNTIF(D17:Y17,1) -> 19 | AB17: =COUNTIF(D17:Y17,0) -> 0 | AC17: =COUNTIF(D17:Y17,"T") -> 0 | AD17: =COUNTIF(D17:Y17,"J") -> 0 | AE17: =SUM(AA17+AC17)/19 -> 1
A18: 7 | B18: =Enero!B18 -> 7 | C18: =Enero!C18 -> Giraldo Ceballos Miguel Angel | D18: 1 | E18: 1 | F18: 1 | G18: 1 | H18: 1 | J18: 1 | K18: 1 | L18: 1 | M18: 1 | N18: 1 | P18: 1 | Q18: 1 | R18: 1 | S18: 1 | T18: 1 | V18: 1 | W18: 1 | X18: 1 | Y18: 1 | AA18: =COUNTIF(D18:Y18,1) -> 19 | AB18: =COUNTIF(D18:Y18,0) -> 0 | AC18: =COUNTIF(D18:Y18,"T") -> 0 | AD18: =COUNTIF(D18:Y18,"J") -> 0 | AE18: =SUM(AA18+AC18)/19 -> 1
A19: 8 | B19: =Enero!B19 -> 7 | C19: =Enero!C19 -> Hincapié Muñoz Juan Pablo | D19: 1 | E19: 1 | F19: 1 | G19: 1 | H19: 1 | J19: 1 | K19: 1 | L19: 1 | M19: 1 | N19: 1 | P19: 1 | Q19: 1 | R19: 1 | S19: 1 | T19: 1 | V19: 1 | W19: 1 | X19: 1 | Y19: 1 | AA19: =COUNTIF(D19:Y19,1) -> 19 | AB19: =COUNTIF(D19:Y19,0) -> 0 | AC19: =COUNTIF(D19:Y19,"T") -> 0 | AD19: =COUNTIF(D19:Y19,"J") -> 0 | AE19: =SUM(AA19+AC19)/19 -> 1
A20: 9 | B20: =Enero!B20 -> 7 | C20: =Enero!C20 -> Jiménez Muñoz Alejandro | D20: 1 | E20: 1 | F20: 1 | G20: 1 | H20: 1 | J20: 1 | K20: 1 | L20: 1 | M20: 1 | N20: 1 | P20: 1 | Q20: 1 | R20: 1 | S20: 1 | T20: 1 | V20: 1 | W20: 1 | X20: 1 | Y20: 1 | AA20: =COUNTIF(D20:Y20,1) -> 19 | AB20: =COUNTIF(D20:Y20,0) -> 0 | AC20: =COUNTIF(D20:Y20,"T") -> 0 | AD20: =COUNTIF(D20:Y20,"J") -> 0 | AE20: =SUM(AA20+AC20)/19 -> 1
A21: 10 | B21: =Enero!B21 -> 7 | C21: =Enero!C21 -> Rodríguez Correa Dubian Esteban | D21: 1 | E21: 1 | F21: 1 | G21: 1 | H21: 1 | J21: 1 | K21: 1 | L21: 1 | M21: 1 | N21: 1 | P21: 1 | Q21: 1 | R21: 1 | S21: 1 | T21: 1 | V21: 1 | W21: 1 | X21: 1 | Y21: 1 | AA21: =COUNTIF(D21:Y21,1) -> 19 | AB21: =COUNTIF(D21:Y21,0) -> 0 | AC21: =COUNTIF(D21:Y21,"T") -> 0 | AD21: =COUNTIF(D21:Y21,"J") -> 0 | AE21: =SUM(AA21+AC21)/19 -> 1
A22: 11 | B22: =Enero!B22 -> 7 | C22: =Enero!C22 -> Valencia Virgen Alexandra | D22: 1 | E22: 1 | F22: 1 | G22: 1 | H22: 1 | J22: 1 | K22: 1 | L22: 1 | M22: 1 | N22: 1 | P22: 1 | Q22: 1 | R22: 1 | S22: 1 | T22: 1 | V22: 1 | W22: 1 | X22: 1 | Y22: 1 | AA22: =COUNTIF(D22:Y22,1) -> 19 | AB22: =COUNTIF(D22:Y22,0) -> 0 | AC22: =COUNTIF(D22:Y22,"T") -> 0 | AD22: =COUNTIF(D22:Y22,"J") -> 0 | AE22: =SUM(AA22+AC22)/19 -> 1
A23: 12 | B23: =Enero!B23 -> 8 | C23: =Enero!C23 -> Caviedes Hernández Juan Manuel | D23: 1 | E23: 1 | F23: 1 | G23: 1 | H23: 1 | J23: 1 | K23: 1 | L23: 1 | M23: 1 | N23: 1 | P23: 1 | Q23: 1 | R23: 1 | S23: 1 | T23: 1 | V23: 1 | W23: 1 | X23: 1 | Y23: 1 | AA23: =COUNTIF(D23:Y23,1) -> 19 | AB23: =COUNTIF(D23:Y23,0) -> 0 | AC23: =COUNTIF(D23:Y23,"T") -> 0 | AD23: =COUNTIF(D23:Y23,"J") -> 0 | AE23: =SUM(AA23+AC23)/19 -> 1
A24: 13 | B24: =Enero!B24 -> 8 | C24: =Enero!C24 -> Orozco Chavarría Cristóbal | D24: 1 | E24: 1 | F24: 1 | G24: 1 | H24: 1 | J24: 1 | K24: 1 | L24: 1 | M24: 1 | N24: 1 | P24: 1 | Q24: 1 | R24: 1 | S24: 1 | T24: 1 | V24: 1 | W24: 1 | X24: 1 | Y24: 1 | AA24: =COUNTIF(D24:Y24,1) -> 19 | AB24: =COUNTIF(D24:Y24,0) -> 0 | AC24: =COUNTIF(D24:Y24,"T") -> 0 | AD24: =COUNTIF(D24:Y24,"J") -> 0 | AE24: =SUM(AA24+AC24)/19 -> 1
A25: 14 | B25: =Enero!B25 -> 8 | C25: =Enero!C25 -> Velásquez Muñoz Anyely Tatiana | D25: 1 | E25: 1 | F25: 1 | G25: 1 | H25: 1 | J25: 1 | K25: 1 | L25: 1 | M25: 1 | N25: 1 | P25: 1 | Q25: 1 | R25: 1 | S25: 1 | T25: 1 | V25: 1 | W25: 1 | X25: 1 | Y25: 1 | AA25: =COUNTIF(D25:Y25,1) -> 19 | AB25: =COUNTIF(D25:Y25,0) -> 0 | AC25: =COUNTIF(D25:Y25,"T") -> 0 | AD25: =COUNTIF(D25:Y25,"J") -> 0 | AE25: =SUM(AA25+AC25)/19 -> 1
A26: 15 | B26: =Enero!B26 -> 9 | C26: =Enero!C26 -> Dávila Bedoya Evelin Sofía | D26: 0 | E26: 0 | F26: 0 | G26: 0 | H26: 0 | J26: 0 | K26: 0 | L26: 0 | M26: 0 | N26: 0 | P26: 0 | Q26: 0 | R26: 0 | S26: 0 | T26: 0 | V26: 0 | W26: 0 | X26: 0 | Y26: 0 | AA26: =COUNTIF(D26:Y26,1) -> 0 | AB26: =COUNTIF(D26:Y26,0) -> 19 | AC26: =COUNTIF(D26:Y26,"T") -> 0 | AD26: =COUNTIF(D26:Y26,"J") -> 0 | AE26: =SUM(AA26+AC26)/19 -> 0
A27: 16 | B27: =Enero!B27 -> 9 | C27: =Enero!C27 -> Duque Aristizabal Ángel Gabriel | D27: 1 | E27: 1 | F27: 1 | G27: 1 | H27: 1 | J27: 1 | K27: 1 | L27: 1 | M27: 1 | N27: 1 | P27: 1 | Q27: 1 | R27: 1 | S27: 1 | T27: 1 | V27: 1 | W27: 1 | X27: 1 | Y27: 1 | AA27: =COUNTIF(D27:Y27,1) -> 19 | AB27: =COUNTIF(D27:Y27,0) -> 0 | AC27: =COUNTIF(D27:Y27,"T") -> 0 | AD27: =COUNTIF(D27:Y27,"J") -> 0 | AE27: =SUM(AA27+AC27)/19 -> 1
... A36: 25 | B36: =Enero!B36 -> 10 | C36: =Enero!C36 -> Gómez Pamplona Julieta | D36: 1 | E36: 1 | F36: 1 | G36: 1 | H36: 1 | J36: 1 | K36: 1 | L36: 1 | M36: 1 | N36: 1 | P36: 1 | Q36: 1 | R36: 1 | S36: 1 | T36: 1 | V36: 1 | W36: 1 | X36: 1 | Y36: 1 | AA36: =COUNTIF(D36:Y36,1) -> 19 | AB36: =COUNTIF(D36:Y36,0) -> 0 | AC36: =COUNTIF(D36:Y36,"T") -> 0 | AD36: =COUNTIF(D36:Y36,"J") -> 0 | AE36: =SUM(AA36+AC36)/19 -> 1
A37: 26 | B37: =Enero!B37 -> 10 | C37: =Enero!C37 -> González Martínez Salomé | D37: 1 | E37: 1 | F37: 1 | G37: 1 | H37: 1 | J37: 1 | K37: 1 | L37: 1 | M37: 1 | N37: 1 | P37: 1 | Q37: 1 | R37: 1 | S37: 1 | T37: 1 | V37: 1 | W37: 1 | X37: 1 | Y37: 1
A38: 27 | B38: 10 | C38: Lezcano Morillo Edwin Alexander | D38: 1 | E38: 1 | F38: 1 | G38: 1 | H38: 1 | J38: 1 | K38: 1 | L38: 1 | M38: 1 | N38: 1 | P38: 1 | Q38: 1 | R38: 1 | S38: 1 | T38: 1 | V38: 1 | W38: 1 | X38: 1 | Y38: 1
A39: 28 | B39: =Enero!B39 -> 10 | C39: =Enero!C39 -> Valencia Vásquez Anderson | D39: 1 | E39: 1 | F39: 1 | G39: 1 | H39: 1 | J39: 1 | K39: 1 | L39: 1 | M39: 1 | N39: 1 | P39: 1 | Q39: 1 | R39: 1 | S39: 1 | T39: 1 | V39: 1 | W39: 1 | X39: 1 | Y39: 1
A40: 29 | B40: =Enero!B40 -> 11 | C40: =Enero!C40 -> Caviedes Hernández Cristina | D40: 1 | E40: 1 | F40: 1 | G40: 1 | H40: 1 | J40: 1 | K40: 1 | L40: 1 | M40: 1 | N40: 1 | P40: 1 | Q40: 1 | R40: 1 | S40: 1 | T40: 1 | V40: 1 | W40: 1 | X40: 1 | Y40: 1

Sheet Mayo
C2: #VALUE! | AA2: Código: IERLJ_AE_06
AA4: Página: 1 de 1
AA6: Versión: 1.0
C7: SEGUIMIENTO A LA ASISTENCIA
A9: Docente: | H9: Sede | T9: Área/Asignaura
A10: Sede | K10: Mes | AA10: Año
A11: N° | B11: GRADO | C11: NOMBRES Y APELLIDOS | D11: 4 | E11: 5 | F11: 6 | G11: 7 | H11: 8 | J11: 11 | K11: 12 | L11: 13 | M11: 14 | N11: 15 | P11: 19 | Q11: 20 | R11: 21 | S11: 22 | U11: 25 | V11: 26 | W11: 27 | X11: 28 | Y11: 29 | AA11: ASISTENCIA | AB11: FALTAS | AC11: TARDE | AD11: JUSTIFICACIÓN | AE11: % ASISTENCIA | AH11: VALORES PARA LLENAR LA ASISTENCIA
A12: 1 | B12: 6 | C12: FRANCO BARRAZA MARIA JOSE | D12: 1 | E12: 1 | F12: 1 | G12: 1 | H12: 1 | J12: 1 | K12: 1 | L12: 1 | M12: 1 | N12: 1 | P12: 1 | Q12: 1 | R12: 1 | S12: 1 | U12: 1 | V12: 1 | W12: 1 | X12: 1 | Y12: 1 | AA12: =COUNTIF(D12:Y12,1) -> 19 | AB12: =COUNTIF(D12:Y12,0) -> 0 | AC12: =COUNTIF(D12:Y12,"T") -> 0 | AD12: =COUNTIF(D12:Y12,"J") -> 0 | AE12: =SUM(AA12+AC12)/19 -> 1 | AI12: 1 | AJ12: Asistio
A13: 2 | B13: 6 | C13: VERA FIGUERA BRANYELIS DEL CARMEN | D13: 1 | E13: 1 | F13: 1 | G13: 1 | H13: 1 | J13: 1 | K13: 1 | L13: 1 | M13: 1 | N13: 1 | P13: 1 | Q13: 1 | R13: 1 | S13: 1 | U13: 1 | V13: 1 | W13: 1 | X13: 1 | Y13: 1 | AA13: =COUNTIF(D13:Y13,1) -> 19 | AB13: =COUNTIF(D13:Y13,0) -> 0 | AC13: =COUNTIF(D13:Y13,"T") -> 0 | AD13: =COUNTIF(D13:Y13,"J") -> 0 | AE13: =SUM(AA13+AC13)/19 -> 1 | AI13: 0 | AJ13: No asistio (faltas)
A14: 3 | B14: 6 | C14: BARRIENTOS GALLO JUAN SEBASTIAN | D14: 1 | E14: 1 | F14: 1 | G14: 1 | H14: 1 | J14: 1 | K14: 1 | L14: 1 | M14: 1 | N14: 1 | P14: 1 | Q14: 1 | R14: 1 | S14: 1 | U14: 1 | V14: 1 | W14: 1 | X14: 1 | Y14: 1 | AA14: =COUNTIF(D14:Y14,1) -> 19 | AB14: =COUNTIF(D14:Y14,0) -> 0 | AC14: =COUNTIF(D14:Y14,"T") -> 0 | AD14: =COUNTIF(D14:Y14,"J") -> 0 | AE14: =SUM(AA14+AC14)/19 -> 1 | AI14: T | AJ14: Llegada tarde
A15: 4 | B15: 7 | C15: ADRIANZA FIGUERA BRAINER JOSUÉ | D15: 1 | E15: 1 | F15: 1 | G15: 1 | H15: 1 | J15: 1 | K15: 1 | L15: 1 | M15: 1 | N15: 1 | P15: 1 | Q15: 1 | R15: 1 | S15: 1 | U15: 1 | V15: 1 | W15: 1 | X15: 1 | Y15: 1 | AA15: =COUNTIF(D15:Y15,1) -> 19 | AB15: =COUNTIF(D15:Y15,0) -> 0 | AC15: =COUNTIF(D15:Y15,"T") -> 0 | AD15: =COUNTIF(D15:Y15,"J") -> 0 | AE15: =SUM(AA15+AC15)/19 -> 1 | AI15: J | AJ15: Justificación
A16: 5 | B16: 7 | C16: CHAVARRÍA VALENCIA DYLAN ALEXIS | D16: 1 | E16: 1 | F16: 1 | G16: 1 | H16: 1 | J16: 1 | K16: 1 | L16: 1 | M16: 1 | N16: 1 | P16: 1 | Q16: 1 | R16: 1 | S16: 1 | U16: 1 | V16: 1 | W16: 1 | X16: 1 | Y16: 1 | AA16: =COUNTIF(D16:Y16,1) -> 19 | AB16: =COUNTIF(D16:Y16,0) -> 0 | AC16: =COUNTIF(D16:Y16,"T") -> 0 | AD16: =COUNTIF(D16:Y16,"J") -> 0 | AE16: =SUM(AA16+AC16)/19 -> 1
A17: 6 | B17: 7 | C17: GIRALDO CEBALLOS MIGUEL ANGEL | D17: 1 | E17: 1 | F17: 1 | G17: 1 | H17: 1 | J17: 1 | K17: 1 | L17: 1 | M17: 1 | N17: 1 | P17: 1 | Q17: 1 | R17: 1 | S17: 1 | U17: 1 | V17: 1 | W17: 1 | X17: 1 | Y17: 1 | AA17: =COUNTIF(D17:Y17,1) -> 19 | AB17: =COUNTIF(D17:Y17,0) -> 0 | AC17: =COUNTIF(D17:Y17,"T") -> 0 | AD17: =COUNTIF(D17:Y17,"J") -> 0 | AE17: =SUM(AA17+AC17)/19 -> 1
A18: 7 | B18: 7 | C18: HINCAPIÉ MUÑOZ JUAN PABLO | D18: 1 | E18: 1 | F18: 1 | G18: 1 | H18: 1 | J18: 1 | K18: 1 | L18: 1 | M18: 1 | N18: 1 | P18: 1 | Q18: 1 | R18: 1 | S18: 1 | U18: 1 | V18: 1 | W18: 1 | X18: 1 | Y18: 1 | AA18: =COUNTIF(D18:Y18,1) -> 19 | AB18: =COUNTIF(D18:Y18,0) -> 0 | AC18: =COUNTIF(D18:Y18,"T") -> 0 | AD18: =COUNTIF(D18:Y18,"J") -> 0 | AE18: =SUM(AA18+AC18)/19 -> 1
A19: 8 | B19: 7 | C19: JIMÉNEZ MUÑOZ ALEJANDRO | D19: 1 | E19: 1 | F19: 1 | G19: 1 | H19: 1 | J19: 1 | K19: 1 | L19: 1 | M19: 1 | N19: 1 | P19: 1 | Q19: 1 | R19: 1 | S19: 1 | U19: 1 | V19: 1 | W19: 1 | X19: 1 | Y19: 1 | AA19: =COUNTIF(D19:Y19,1) -> 19 | AB19: =COUNTIF(D19:Y19,0) -> 0 | AC19: =COUNTIF(D19:Y19,"T") -> 0 | AD19: =COUNTIF(D19:Y19,"J") -> 0 | AE19: =SUM(AA19+AC19)/19 -> 1
A20: 9 | B20: 7 | C20: RODRÍGUEZ CORREA DUBIAN ESTEBAN | D20: 1 | E20: 1 | F20: 1 | G20: 1 | H20: 1 | J20: 1 | K20: 1 | L20: 1 | M20: 1 | N20: 1 | P20: 1 | Q20: 1 | R20: 1 | S20: 1 | U20: 1 | V20: 1 | W20: 1 | X20: 1 | Y20: 1 | AA20: =COUNTIF(D20:Y20,1) -> 19 | AB20: =COUNTIF(D20:Y20,0) -> 0 | AC20: =COUNTIF(D20:Y20,"T") -> 0 | AD20: =COUNTIF(D20:Y20,"J") -> 0 | AE20: =SUM(AA20+AC20)/19 -> 1
A21: 10 | B21: 7 | C21: VALENCIA VIRGEN ALEXANDRA | D21: 1 | E21: 1 | F21: 1 | G21: 1 | H21: 1 | J21: 1 | K21: 1 | L21: 1 | M21: 1 | N21: 1 | P21: 1 | Q21: 1 | R21: 1 | S21: 1 | U21: 1 | V21: 1 | W21: 1 | X21: 1 | Y21: 1 | AA21: =COUNTIF(D21:Y21,1) -> 19 | AB21: =COUNTIF(D21:Y21,0) -> 0 | AC21: =COUNTIF(D21:Y21,"T") -> 0 | AD21: =COUNTIF(D21:Y21,"J") -> 0 | AE21: =SUM(AA21+AC21)/19 -> 1
A22: 11 | B22: 8 | C22: CAVIEDES HERNÁNDEZ JUAN MANUEL | D22: 1 | E22: 1 | F22: 1 | G22: 1 | H22: 1 | J22: 1 | K22: 1 | L22: 1 | M22: 1 | N22: 1 | P22: 1 | Q22: 1 | R22: 1 | S22: 1 | U22: 1 | V22: 1 | W22: 1 | X22: 1 | Y22: 1 | AA22: =COUNTIF(D22:Y22,1) -> 19 | AB22: =COUNTIF(D22:Y22,0) -> 0 | AC22: =COUNTIF(D22:Y22,"T") -> 0 | AD22: =COUNTIF(D22:Y22,"J") -> 0 | AE22: =SUM(AA22+AC22)/19 -> 1
A23: 12 | B23: 8 | C23: OROZCO CHAVARRÍA CRISTÓBAL | D23: 1 | E23: 1 | F23: 1 | G23: 1 | H23: 1 | J23: 1 | K23: 1 | L23: 1 | M23: 1 | N23: 1 | P23: 1 | Q23: 1 | R23: 1 | S23: 1 | U23: 1 | V23: 1 | W23: 1 | X23: 1 | Y23: 1 | AA23: =COUNTIF(D23:Y23,1) -> 19 | AB23: =COUNTIF(D23:Y23,0) -> 0 | AC23: =COUNTIF(D23:Y23,"T") -> 0 | AD23: =COUNTIF(D23:Y23,"J") -> 0 | AE23: =SUM(AA23+AC23)/19 -> 1
A24: 13 | B24: 8 | C24: VELÁSQUEZ MUÑOZ ANYELY TATIANA | D24: 1 | E24: 1 | F24: 1 | G24: 1 | H24: 1 | J24: 1 | K24: 1 | L24: 1 | M24: 1 | N24: 1 | P24: 1 | Q24: 1 | R24: 1 | S24: 1 | U24: 1 | V24: 1 | W24: 1 | X24: 1 | Y24: 1 | AA24: =COUNTIF(D24:Y24,1) -> 19 | AB24: =COUNTIF(D24:Y24,0) -> 0 | AC24: =COUNTIF(D24:Y24,"T") -> 0 | AD24: =COUNTIF(D24:Y24,"J") -> 0 | AE24: =SUM(AA24+AC24)/19 -> 1
A25: 14 | B25: 8 | C25: LEZCANO MORILLO DUVAN ALEXANDER | D25: 1 | E25: 1 | F25: 1 | G25: 1 | H25: 1 | J25: 1 | K25: 1 | L25: 1 | M25: 1 | N25: 1 | P25: 1 | Q25: 1 | R25: 1 | S25: 1 | U25: 1 | V25: 1 | W25: 1 | X25: 1 | Y25: 1 | AA25: =COUNTIF(D25:Y25,1) -> 19 | AB25: =COUNTIF(D25:Y25,0) -> 0 | AC25: =COUNTIF(D25:Y25,"T") -> 0 | AD25: =COUNTIF(D25:Y25,"J") -> 0 | AE25: =SUM(AA25+AC25)/19 -> 1
A26: 15 | B26: 8 | C26: CASTRILLON HERRERA JUAN PABLO | D26: 1 | E26: 1 | F26: 1 | G26: 1 | H26: 1 | J26: 1 | K26: 1 | L26: 1 | M26: 1 | N26: 1 | P26: 1 | Q26: 1 | R26: 1 | S26: 1 | U26: 1 | V26: 1 | W26: 1 | X26: 1 | Y26: 1 | AA26: =COUNTIF(D26:Y26,1) -> 19 | AB26: =COUNTIF(D26:Y26,0) -> 0 | AC26: =COUNTIF(D26:Y26,"T") -> 0 | AD26: =COUNTIF(D26:Y26,"J") -> 0 | AE26: =SUM(AA26+AC26)/19 -> 1
A27: 16 | B27: 9 | C27: DUQUE ARISTIZABAL ÁNGEL GABRIEL | D27: 1 | E27: 1 | F27: 1 | G27: 1 | H27: 1 | J27: 1 | K27: 1 | L27: 1 | M27: 1 | N27: 1 | P27: 1 | Q27: 1 | R27: 1 | S27: 1 | U27: 1 | V27: 1 | W27: 1 | X27: 1 | Y27: 1 | AA27: =COUNTIF(D27:Y27,1) -> 19 | AB27: =COUNTIF(D27:Y27,0) -> 0 | AC27: =COUNTIF(D27:Y27,"T") -> 0 | AD27: =COUNTIF(D27:Y27,"J") -> 0 | AE27: =SUM(AA27+AC27)/19 -> 1
... A36: 25 | B36: 10 | C36: GONZÁLEZ MARTÍNEZ SALOMÉ | D36: 1 | E36: 1 | F36: 1 | G36: 1 | H36: 1 | J36: 1 | K36: 1 | L36: 1 | M36: 1 | N36: 1 | P36: 1 | Q36: 1 | R36: 1 | S36: 1 | U36: 1 | V36: 1 | W36: 1 | X36: 1 | Y36: 1 | AA36: =COUNTIF(D36:Y36,1) -> 19 | AB36: =COUNTIF(D36:Y36,0) -> 0 | AC36: =COUNTIF(D36:Y36,"T") -> 0 | AD36: =COUNTIF(D36:Y36,"J") -> 0 | AE36: =SUM(AA36+AC36)/19 -> 1
A37: 26 | B37: 10 | C37: LEZCANO MORILLO EDWIN ALEXANDER | D37: 1 | E37: 1 | F37: 1 | G37: 1 | H37: 1 | J37: 1 | K37: 1 | L37: 1 | M37: 1 | N37: 1 | P37: 1 | Q37: 1 | R37: 1 | S37: 1 | U37: 1 | V37: 1 | W37: 1 | X37: 1 | Y37: 1
A38: 27 | B38: 10 | C38: VALENCIA VÁSQUEZ ANDERSON | D38: 1 | E38: 1 | F38: 1 | G38: 1 | H38: 1 | J38: 1 | K38: 1 | L38: 1 | M38: 1 | N38: 1 | P38: 1 | Q38: 1 | R38: 1 | S38: 1 | U38: 1 | V38: 1 | W38: 1 | X38: 1 | Y38: 1
A39: 28 | B39: 11 | C39: CAVIEDES HERNÁNDEZ CRISTINA | D39: 1 | E39: 1 | F39: 1 | G39: 1 | H39: 1 | J39: 1 | K39: 1 | L39: 1 | M39: 1 | N39: 1 | P39: 1 | Q39: 1 | R39: 1 | S39: 1 | U39: 1 | V39: 1 | W39: 1 | X39: 1 | Y39: 1

Sheet Junio
C2: #VALUE! | AA2: Código: IERLJ_AE_06
AA4: Página: 1 de 1
AA6: Versión: 1.0
C7: SEGUIMIENTO A LA ASISTENCIA
A9: Docente: | H9: Sede | T9: Área/Asignaura
A10: Sede | K10: Mes | AA10: Año
A11: N° | B11: GRADO | C11: NOMBRES Y APELLIDOS | D11: 1 | E11: 2 | F11: 3 | G11: 4 | H11: 5 | J11: 9 | K11: 10 | L11: 11 | M11: 12 | O11: 16 | P11: 17 | Q11: 18 | R11: 19 | S11: 23 | T11: 26 | U11: 24 | V11: 25 | W11: 26 | X11: 29 | Y11: 30 | Z11: ASISTENCIA | AA11: FALTAS | AB11: TARDE | AC11: JUSTIFICACIÓN | AD11: % ASISTENCIA | AG11: VALORES PARA LLENAR LA ASISTENCIA
A12: 1 | B12: 6 | C12: FRANCO BARRAZA MARIA JOSE | D12: 1 | E12: 1 | F12: 1 | G12: 1 | H12: 1 | J12: 1 | K12: 1 | L12: 1 | Z12: =COUNTIF(D12:Y12,1) -> 8 | AA12: =COUNTIF(D12:Y12,0) -> 0 | AB12: =COUNTIF(D12:Y12,"T") -> 0 | AC12: =COUNTIF(D12:Y12,"J") -> 0 | AD12: =SUM(Z12+AB12)/9 -> 0.88888889 | AH12: 1 | AI12: Asistio
A13: 2 | B13: 6 | C13: VERA FIGUERA BRANYELIS DEL CARMEN | D13: 1 | E13: 1 | F13: 1 | G13: 1 | H13: 1 | J13: 1 | K13: 1 | L13: 0 | Z13: =COUNTIF(D13:Y13,1) -> 7 | AA13: =COUNTIF(D13:Y13,0) -> 1 | AB13: =COUNTIF(D13:Y13,"T") -> 0 | AC13: =COUNTIF(D13:Y13,"J") -> 0 | AD13: =SUM(Z13+AB13)/9 -> 0.77777778 | AH13: 0 | AI13: No asistio (faltas)
A14: 3 | B14: 6 | C14: BARRIENTOS GALLO JUAN SEBASTIAN | D14: 1 | E14: 1 | F14: 1 | G14: 1 | H14: 1 | J14: 1 | K14: 1 | L14: 1 | Z14: =COUNTIF(D14:Y14,1) -> 8 | AA14: =COUNTIF(D14:Y14,0) -> 0 | AB14: =COUNTIF(D14:Y14,"T") -> 0 | AC14: =COUNTIF(D14:Y14,"J") -> 0 | AD14: =SUM(Z14+AB14)/9 -> 0.88888889 | AH14: T | AI14: Llegada tarde
A15: 4 | B15: 7 | C15: ADRIANZA FIGUERA BRAINER JOSUÉ | D15: 1 | E15: 1 | F15: 1 | G15: 1 | H15: 1 | J15: 1 | K15: 1 | L15: 1 | Z15: =COUNTIF(D15:Y15,1) -> 8 | AA15: =COUNTIF(D15:Y15,0) -> 0 | AB15: =COUNTIF(D15:Y15,"T") -> 0 | AC15: =COUNTIF(D15:Y15,"J") -> 0 | AD15: =SUM(Z15+AB15)/9 -> 0.88888889 | AH15: J | AI15: Justificación
A16: 5 | B16: 7 | C16: CHAVARRÍA VALENCIA DYLAN ALEXIS | D16: 1 | E16: 1 | F16: 1 | G16: 1 | H16: 1 | J16: 1 | K16: 1 | L16: 1 | Z16: =COUNTIF(D16:Y16,1) -> 8 | AA16: =COUNTIF(D16:Y16,0) -> 0 | AB16: =COUNTIF(D16:Y16,"T") -> 0 | AC16: =COUNTIF(D16:Y16,"J") -> 0 | AD16: =SUM(Z16+AB16)/9 -> 0.88888889 | AH16: U | AI16: Uniforme
A17: 6 | B17: 7 | C17: GIRALDO CEBALLOS MIGUEL ANGEL | D17: 1 | E17: 1 | F17: 1 | G17: 1 | H17: 1 | J17: 1 | K17: 1 | L17: 1 | Z17: =COUNTIF(D17:Y17,1) -> 8 | AA17: =COUNTIF(D17:Y17,0) -> 0 | AB17: =COUNTIF(D17:Y17,"T") -> 0 | AC17: =COUNTIF(D17:Y17,"J") -> 0 | AD17: =SUM(Z17+AB17)/9 -> 0.88888889
